01-04 02:23:05 [ERROR] nonebot | Running Matcher(type='message', module=zhenxun.plugins.parse_bilibili, lineno=54) failed.
Traceback (most recent call last):

  File "C:\Program Files\zhenxun\zhenxun_bot-dev\bot.py", line 27, in <module>
    nonebot.run()
    │       └ <function run at 0x000001892EB86290>
    └ <module 'nonebot' from 'C:\\Users\\Administrator\\AppData\\Local\\pypoetry\\Cache\\virtualenvs\\zhenxun-bot-k9jvl_fX-py3.10\\...

  File "C:\Users\Administrator\AppData\Local\pypoetry\Cache\virtualenvs\zhenxun-bot-k9jvl_fX-py3.10\lib\site-packages\nonebot\__init__.py", line 335, in run
    get_driver().run(*args, **kwargs)
    │                 │       └ {}
    │                 └ ()
    └ <function get_driver at 0x000001892EB860E0>

  File "C:\Users\Administrator\AppData\Local\pypoetry\Cache\virtualenvs\zhenxun-bot-k9jvl_fX-py3.10\lib\site-packages\nonebot\drivers\fastapi.py", line 186, in run
    uvicorn.run(
    │       └ <function run at 0x000001892F35BD00>
    └ <module 'uvicorn' from 'C:\\Users\\Administrator\\AppData\\Local\\pypoetry\\Cache\\virtualenvs\\zhenxun-bot-k9jvl_fX-py3.10\\...

  File "C:\Users\Administrator\AppData\Local\pypoetry\Cache\virtualenvs\zhenxun-bot-k9jvl_fX-py3.10\lib\site-packages\uvicorn\main.py", line 579, in run
    server.run()
    │      └ <function Server.run at 0x000001892F35B640>
    └ <uvicorn.server.Server object at 0x000001893EFF22F0>

  File "C:\Users\Administrator\AppData\Local\pypoetry\Cache\virtualenvs\zhenxun-bot-k9jvl_fX-py3.10\lib\site-packages\uvicorn\server.py", line 65, in run
    return asyncio.run(self.serve(sockets=sockets))
           │       │   │    │             └ None
           │       │   │    └ <function Server.serve at 0x000001892F35B6D0>
           │       │   └ <uvicorn.server.Server object at 0x000001893EFF22F0>
           │       └ <function run at 0x000001892C870E50>
           └ <module 'asyncio' from 'C:\\Users\\Administrator\\AppData\\Local\\Programs\\Python\\Python310\\lib\\asyncio\\__init__.py'>

  File "C:\Users\Administrator\AppData\Local\Programs\Python\Python310\lib\asyncio\runners.py", line 44, in run
    return loop.run_until_complete(main)
           │    │                  └ <coroutine object Server.serve at 0x00000189316A34C0>
           │    └ <function BaseEventLoop.run_until_complete at 0x000001892C970280>
           └ <ProactorEventLoop running=True closed=False debug=False>

  File "C:\Users\Administrator\AppData\Local\Programs\Python\Python310\lib\asyncio\base_events.py", line 636, in run_until_complete
    self.run_forever()
    │    └ <function ProactorEventLoop.run_forever at 0x000001892E5B1510>
    └ <ProactorEventLoop running=True closed=False debug=False>

  File "C:\Users\Administrator\AppData\Local\Programs\Python\Python310\lib\asyncio\windows_events.py", line 321, in run_forever
    super().run_forever()

  File "C:\Users\Administrator\AppData\Local\Programs\Python\Python310\lib\asyncio\base_events.py", line 603, in run_forever
    self._run_once()
    │    └ <function BaseEventLoop._run_once at 0x000001892C971CF0>
    └ <ProactorEventLoop running=True closed=False debug=False>

  File "C:\Users\Administrator\AppData\Local\Programs\Python\Python310\lib\asyncio\base_events.py", line 1909, in _run_once
    handle._run()
    │      └ <function Handle._run at 0x000001892C9209D0>
    └ <Handle Task.task_wakeup(<_GatheringFu...7da5983'}})]]>)>

  File "C:\Users\Administrator\AppData\Local\Programs\Python\Python310\lib\asyncio\events.py", line 80, in _run
    self._context.run(self._callback, *self._args)
    │    │            │    │           │    └ <member '_args' of 'Handle' objects>
    │    │            │    │           └ <Handle Task.task_wakeup(<_GatheringFu...7da5983'}})]]>)>
    │    │            │    └ <member '_callback' of 'Handle' objects>
    │    │            └ <Handle Task.task_wakeup(<_GatheringFu...7da5983'}})]]>)>
    │    └ <member '_context' of 'Handle' objects>
    └ <Handle Task.task_wakeup(<_GatheringFu...7da5983'}})]]>)>

  File "C:\Users\Administrator\AppData\Local\pypoetry\Cache\virtualenvs\zhenxun-bot-k9jvl_fX-py3.10\lib\site-packages\nonebot\message.py", line 476, in check_and_run_matcher
    await _run_matcher(
          └ <function _run_matcher at 0x000001892ECD5750>

> File "C:\Users\Administrator\AppData\Local\pypoetry\Cache\virtualenvs\zhenxun-bot-k9jvl_fX-py3.10\lib\site-packages\nonebot\message.py", line 428, in _run_matcher
    await matcher.run(bot, event, state, stack, dependency_cache)
          │       │   │    │      │      │      └ {<function _event_to_me at 0x000001892EBE6A70>: <Task finished name='Task-2597037' coro=<_event_to_me() done, defined at C:\U...
          │       │   │    │      │      └ <contextlib.AsyncExitStack object at 0x000001893F81A7A0>
          │       │   │    │      └ {'_prefix': {'command': None, 'raw_command': None, 'command_arg': None, 'command_start': None, 'command_whitespace': None}}
          │       │   │    └ PrivateMessageEvent(time=1735928585, self_id=3973508735, post_type='message', sub_type='friend', user_id=2747277822, message_...
          │       │   └ Bot(type='OneBot V11', self_id='3973508735')
          │       └ <function Matcher.run at 0x000001892EBE68C0>
          └ Matcher(type='message', module=zhenxun.plugins.parse_bilibili, lineno=54)

  File "C:\Users\Administrator\AppData\Local\pypoetry\Cache\virtualenvs\zhenxun-bot-k9jvl_fX-py3.10\lib\site-packages\nonebot\internal\matcher\matcher.py", line 850, in run
    await self.simple_run(bot, event, state, stack, dependency_cache)
          │    │          │    │      │      │      └ {<function _event_to_me at 0x000001892EBE6A70>: <Task finished name='Task-2597037' coro=<_event_to_me() done, defined at C:\U...
          │    │          │    │      │      └ <contextlib.AsyncExitStack object at 0x000001893F81A7A0>
          │    │          │    │      └ {'_prefix': {'command': None, 'raw_command': None, 'command_arg': None, 'command_start': None, 'command_whitespace': None}}
          │    │          │    └ PrivateMessageEvent(time=1735928585, self_id=3973508735, post_type='message', sub_type='friend', user_id=2747277822, message_...
          │    │          └ Bot(type='OneBot V11', self_id='3973508735')
          │    └ <function Matcher.simple_run at 0x000001892EBE6830>
          └ Matcher(type='message', module=zhenxun.plugins.parse_bilibili, lineno=54)

  File "C:\Users\Administrator\AppData\Local\pypoetry\Cache\virtualenvs\zhenxun-bot-k9jvl_fX-py3.10\lib\site-packages\nonebot\internal\matcher\matcher.py", line 825, in simple_run
    await handler(
          └ Dependent(call=_)

  File "C:\Users\Administrator\AppData\Local\pypoetry\Cache\virtualenvs\zhenxun-bot-k9jvl_fX-py3.10\lib\site-packages\nonebot\dependencies\__init__.py", line 94, in __call__
    return await cast(Callable[..., Awaitable[R]], self.call)(**values)
                 │    │             │         │    │    │       └ {'session': Session(bot_id='3973508735', bot_type='OneBot V11', platform='qq', level=<SessionLevel.LEVEL1: 1>, id1='274727782...
                 │    │             │         │    │    └ <function _ at 0x000001893ED008B0>
                 │    │             │         │    └ Dependent(call=_)
                 │    │             │         └ ~R
                 │    │             └ <class 'collections.abc.Awaitable'>
                 │    └ typing.Callable
                 └ <function cast at 0x000001892C7004C0>

  File "C:\Program Files\zhenxun\zhenxun_bot-dev\zhenxun\plugins\parse_bilibili\__init__.py", line 86, in _
    get_url = (qqdocurl_value if qqdocurl_value else jumpUrl_value).split("?")[
               │                 │                   └ {}
               │                 └ {}
               └ {}

AttributeError: 'dict' object has no attribute 'split'
01-04 02:23:16 [ERROR] nonebot | Running Matcher(type='message', module=zhenxun.plugins.nonebot_plugin_sparkapi.matchers.block_private, lineno=11) failed.
Traceback (most recent call last):

  File "C:\Program Files\zhenxun\zhenxun_bot-dev\bot.py", line 27, in <module>
    nonebot.run()
    │       └ <function run at 0x000001892EB86290>
    └ <module 'nonebot' from 'C:\\Users\\Administrator\\AppData\\Local\\pypoetry\\Cache\\virtualenvs\\zhenxun-bot-k9jvl_fX-py3.10\\...

  File "C:\Users\Administrator\AppData\Local\pypoetry\Cache\virtualenvs\zhenxun-bot-k9jvl_fX-py3.10\lib\site-packages\nonebot\__init__.py", line 335, in run
    get_driver().run(*args, **kwargs)
    │                 │       └ {}
    │                 └ ()
    └ <function get_driver at 0x000001892EB860E0>

  File "C:\Users\Administrator\AppData\Local\pypoetry\Cache\virtualenvs\zhenxun-bot-k9jvl_fX-py3.10\lib\site-packages\nonebot\drivers\fastapi.py", line 186, in run
    uvicorn.run(
    │       └ <function run at 0x000001892F35BD00>
    └ <module 'uvicorn' from 'C:\\Users\\Administrator\\AppData\\Local\\pypoetry\\Cache\\virtualenvs\\zhenxun-bot-k9jvl_fX-py3.10\\...

  File "C:\Users\Administrator\AppData\Local\pypoetry\Cache\virtualenvs\zhenxun-bot-k9jvl_fX-py3.10\lib\site-packages\uvicorn\main.py", line 579, in run
    server.run()
    │      └ <function Server.run at 0x000001892F35B640>
    └ <uvicorn.server.Server object at 0x000001893EFF22F0>

  File "C:\Users\Administrator\AppData\Local\pypoetry\Cache\virtualenvs\zhenxun-bot-k9jvl_fX-py3.10\lib\site-packages\uvicorn\server.py", line 65, in run
    return asyncio.run(self.serve(sockets=sockets))
           │       │   │    │             └ None
           │       │   │    └ <function Server.serve at 0x000001892F35B6D0>
           │       │   └ <uvicorn.server.Server object at 0x000001893EFF22F0>
           │       └ <function run at 0x000001892C870E50>
           └ <module 'asyncio' from 'C:\\Users\\Administrator\\AppData\\Local\\Programs\\Python\\Python310\\lib\\asyncio\\__init__.py'>

  File "C:\Users\Administrator\AppData\Local\Programs\Python\Python310\lib\asyncio\runners.py", line 44, in run
    return loop.run_until_complete(main)
           │    │                  └ <coroutine object Server.serve at 0x00000189316A34C0>
           │    └ <function BaseEventLoop.run_until_complete at 0x000001892C970280>
           └ <ProactorEventLoop running=True closed=False debug=False>

  File "C:\Users\Administrator\AppData\Local\Programs\Python\Python310\lib\asyncio\base_events.py", line 636, in run_until_complete
    self.run_forever()
    │    └ <function ProactorEventLoop.run_forever at 0x000001892E5B1510>
    └ <ProactorEventLoop running=True closed=False debug=False>

  File "C:\Users\Administrator\AppData\Local\Programs\Python\Python310\lib\asyncio\windows_events.py", line 321, in run_forever
    super().run_forever()

  File "C:\Users\Administrator\AppData\Local\Programs\Python\Python310\lib\asyncio\base_events.py", line 603, in run_forever
    self._run_once()
    │    └ <function BaseEventLoop._run_once at 0x000001892C971CF0>
    └ <ProactorEventLoop running=True closed=False debug=False>

  File "C:\Users\Administrator\AppData\Local\Programs\Python\Python310\lib\asyncio\base_events.py", line 1909, in _run_once
    handle._run()
    │      └ <function Handle._run at 0x000001892C9209D0>
    └ <Handle Task.task_wakeup(<_GatheringFu...result=[None]>)>

  File "C:\Users\Administrator\AppData\Local\Programs\Python\Python310\lib\asyncio\events.py", line 80, in _run
    self._context.run(self._callback, *self._args)
    │    │            │    │           │    └ <member '_args' of 'Handle' objects>
    │    │            │    │           └ <Handle Task.task_wakeup(<_GatheringFu...result=[None]>)>
    │    │            │    └ <member '_callback' of 'Handle' objects>
    │    │            └ <Handle Task.task_wakeup(<_GatheringFu...result=[None]>)>
    │    └ <member '_context' of 'Handle' objects>
    └ <Handle Task.task_wakeup(<_GatheringFu...result=[None]>)>

  File "C:\Users\Administrator\AppData\Local\pypoetry\Cache\virtualenvs\zhenxun-bot-k9jvl_fX-py3.10\lib\site-packages\nonebot\message.py", line 476, in check_and_run_matcher
    await _run_matcher(
          └ <function _run_matcher at 0x000001892ECD5750>

> File "C:\Users\Administrator\AppData\Local\pypoetry\Cache\virtualenvs\zhenxun-bot-k9jvl_fX-py3.10\lib\site-packages\nonebot\message.py", line 428, in _run_matcher
    await matcher.run(bot, event, state, stack, dependency_cache)
          │       │   │    │      │      │      └ {<function _event_to_me at 0x000001892EBE6A70>: <Task finished name='Task-2597037' coro=<_event_to_me() done, defined at C:\U...
          │       │   │    │      │      └ <contextlib.AsyncExitStack object at 0x000001893F81A7A0>
          │       │   │    │      └ {'_prefix': {'command': None, 'raw_command': None, 'command_arg': None, 'command_start': None, 'command_whitespace': None}}
          │       │   │    └ PrivateMessageEvent(time=1735928585, self_id=3973508735, post_type='message', sub_type='friend', user_id=2747277822, message_...
          │       │   └ Bot(type='OneBot V11', self_id='3973508735')
          │       └ <function Matcher.run at 0x000001892EBE68C0>
          └ Matcher(type='message', module=zhenxun.plugins.nonebot_plugin_sparkapi.matchers.block_private, lineno=11)

  File "C:\Users\Administrator\AppData\Local\pypoetry\Cache\virtualenvs\zhenxun-bot-k9jvl_fX-py3.10\lib\site-packages\nonebot\internal\matcher\matcher.py", line 850, in run
    await self.simple_run(bot, event, state, stack, dependency_cache)
          │    │          │    │      │      │      └ {<function _event_to_me at 0x000001892EBE6A70>: <Task finished name='Task-2597037' coro=<_event_to_me() done, defined at C:\U...
          │    │          │    │      │      └ <contextlib.AsyncExitStack object at 0x000001893F81A7A0>
          │    │          │    │      └ {'_prefix': {'command': None, 'raw_command': None, 'command_arg': None, 'command_start': None, 'command_whitespace': None}}
          │    │          │    └ PrivateMessageEvent(time=1735928585, self_id=3973508735, post_type='message', sub_type='friend', user_id=2747277822, message_...
          │    │          └ Bot(type='OneBot V11', self_id='3973508735')
          │    └ <function Matcher.simple_run at 0x000001892EBE6830>
          └ Matcher(type='message', module=zhenxun.plugins.nonebot_plugin_sparkapi.matchers.block_private, lineno=11)

  File "C:\Users\Administrator\AppData\Local\pypoetry\Cache\virtualenvs\zhenxun-bot-k9jvl_fX-py3.10\lib\site-packages\nonebot\internal\matcher\matcher.py", line 825, in simple_run
    await handler(
          └ Dependent(call=_)

  File "C:\Users\Administrator\AppData\Local\pypoetry\Cache\virtualenvs\zhenxun-bot-k9jvl_fX-py3.10\lib\site-packages\nonebot\dependencies\__init__.py", line 94, in __call__
    return await cast(Callable[..., Awaitable[R]], self.call)(**values)
                 │    │             │         │    │    │       └ {}
                 │    │             │         │    │    └ <function _ at 0x000001893EC84D30>
                 │    │             │         │    └ Dependent(call=_)
                 │    │             │         └ ~R
                 │    │             └ <class 'collections.abc.Awaitable'>
                 │    └ typing.Callable
                 └ <function cast at 0x000001892C7004C0>

  File "C:\Program Files\zhenxun\zhenxun_bot-dev\zhenxun\plugins\nonebot_plugin_sparkapi\matchers\block_private.py", line 18, in _
    await matcher_blockprivate.finish("私聊功能已关闭！如有需要，请联系管理员。")
          │                    └ <classmethod(<function Matcher.finish at 0x000001892EBE5D80>)>
          └ Matcher(type='message', module=zhenxun.plugins.nonebot_plugin_sparkapi.matchers.block_private, lineno=11)

  File "C:\Users\Administrator\AppData\Local\pypoetry\Cache\virtualenvs\zhenxun-bot-k9jvl_fX-py3.10\lib\site-packages\nonebot\internal\matcher\matcher.py", line 582, in finish
    await cls.send(message, **kwargs)
          │   │    │          └ {}
          │   │    └ '私聊功能已关闭！如有需要，请联系管理员。'
          │   └ <classmethod(<function Matcher.send at 0x000001892EBE5CF0>)>
          └ Matcher(type='message', module=zhenxun.plugins.nonebot_plugin_sparkapi.matchers.block_private, lineno=11)

  File "C:\Users\Administrator\AppData\Local\pypoetry\Cache\virtualenvs\zhenxun-bot-k9jvl_fX-py3.10\lib\site-packages\nonebot\internal\matcher\matcher.py", line 566, in send
    return await bot.send(event=event, message=_message, **kwargs)
                 │   │          │              │           └ {}
                 │   │          │              └ '私聊功能已关闭！如有需要，请联系管理员。'
                 │   │          └ PrivateMessageEvent(time=1735928585, self_id=3973508735, post_type='message', sub_type='friend', user_id=2747277822, message_...
                 │   └ <function Bot.send at 0x000001892F0E4EE0>
                 └ Bot(type='OneBot V11', self_id='3973508735')

  File "C:\Users\Administrator\AppData\Local\pypoetry\Cache\virtualenvs\zhenxun-bot-k9jvl_fX-py3.10\lib\site-packages\nonebot\adapters\onebot\v11\bot.py", line 237, in send
    return await self.__class__.send_handler(self, event, message, **kwargs)
                 │    │                      │     │      │          └ {}
                 │    │                      │     │      └ '私聊功能已关闭！如有需要，请联系管理员。'
                 │    │                      │     └ PrivateMessageEvent(time=1735928585, self_id=3973508735, post_type='message', sub_type='friend', user_id=2747277822, message_...
                 │    │                      └ Bot(type='OneBot V11', self_id='3973508735')
                 │    └ <attribute '__class__' of 'object' objects>
                 └ Bot(type='OneBot V11', self_id='3973508735')

  File "C:\Users\Administrator\AppData\Local\pypoetry\Cache\virtualenvs\zhenxun-bot-k9jvl_fX-py3.10\lib\site-packages\nonebot\adapters\onebot\v11\bot.py", line 190, in send
    return await bot.send_msg(**params)
                 │              └ {'user_id': 2747277822, 'message_type': 'private', 'message': [MessageSegment(type='text', data={'text': '私聊功能已关闭！如有需要，请联系管理员...
                 └ Bot(type='OneBot V11', self_id='3973508735')

  File "C:\Users\Administrator\AppData\Local\pypoetry\Cache\virtualenvs\zhenxun-bot-k9jvl_fX-py3.10\lib\site-packages\nonebot\internal\adapter\bot.py", line 122, in call_api
    raise exception
          └ ActionFailed(status='failed', retcode=1200, data=None, message='Error: Timeout: NTEvent serviceAndMethod:NodeIKernelMsgServic...

  File "C:\Users\Administrator\AppData\Local\pypoetry\Cache\virtualenvs\zhenxun-bot-k9jvl_fX-py3.10\lib\site-packages\nonebot\internal\adapter\bot.py", line 97, in call_api
    result = await self.adapter._call_api(self, api, **data)
                   │    │       │         │     │      └ {'user_id': 2747277822, 'message_type': 'private', 'message': [MessageSegment(type='text', data={'text': '私聊功能已关闭！如有需要，请联系管理员...
                   │    │       │         │     └ 'send_msg'
                   │    │       │         └ Bot(type='OneBot V11', self_id='3973508735')
                   │    │       └ <function Adapter._call_api at 0x000001892C3E8820>
                   │    └ Adapter(name='OneBot V11')
                   └ Bot(type='OneBot V11', self_id='3973508735')

  File "C:\Users\Administrator\AppData\Local\pypoetry\Cache\virtualenvs\zhenxun-bot-k9jvl_fX-py3.10\lib\site-packages\nonebot\adapters\onebot\v11\adapter.py", line 147, in _call_api
    return handle_api_result(await self._result_store.fetch(seq, timeout))
           │                       │    │             │     │    └ 30.0
           │                       │    │             │     └ 2120
           │                       │    │             └ <function ResultStore.fetch at 0x000001892F0E6050>
           │                       │    └ <nonebot.adapters.onebot.store.ResultStore object at 0x000001892EDDD960>
           │                       └ Adapter(name='OneBot V11')
           └ <function handle_api_result at 0x000001892F079000>

  File "C:\Users\Administrator\AppData\Local\pypoetry\Cache\virtualenvs\zhenxun-bot-k9jvl_fX-py3.10\lib\site-packages\nonebot\adapters\onebot\v11\utils.py", line 58, in handle_api_result
    raise ActionFailed(**result)
          │              └ {'status': 'failed', 'retcode': 1200, 'data': None, 'message': 'Error: Timeout: NTEvent serviceAndMethod:NodeIKernelMsgServic...
          └ <class 'nonebot.adapters.onebot.v11.exception.ActionFailed'>

nonebot.adapters.onebot.v11.exception.ActionFailed: ActionFailed(status='failed', retcode=1200, data=None, message='Error: Timeout: NTEvent serviceAndMethod:NodeIKernelMsgService/sendMsg ListenerName:NodeIKernelMsgListener/onMsgInfoListUpdate EventRet:\n{}\n\n    at Timeout.sendDataCallback [as _onTimeout] (file:///C:/Users/Administrator/Documents/LiteloaderQQNT/plugins/NapCat.Framework/napcat.mjs:7666:15)\n    at listOnTimeout (node:internal/timers:573:17)\n    at process.processTimers (node:internal/timers:514:7)', wording='Error: Timeout: NTEvent serviceAndMethod:NodeIKernelMsgService/sendMsg ListenerName:NodeIKernelMsgListener/onMsgInfoListUpdate EventRet:\n{}\n\n    at Timeout.sendDataCallback [as _onTimeout] (file:///C:/Users/Administrator/Documents/LiteloaderQQNT/plugins/NapCat.Framework/napcat.mjs:7666:15)\n    at listOnTimeout (node:internal/timers:573:17)\n    at process.processTimers (node:internal/timers:514:7)', echo='2120')
01-04 04:30:02 [ERROR] zhenxun | 下载 ['https://i.pixiv.re/img-original/img/2023/09/08/00/01/37/111530368_p0.jpg'] 错误 Path：C:\Program Files\zhenxun\zhenxun_bot-dev\resources\temp\4.jpg || 错误 <class 'httpx.ConnectError'>: 
01-04 04:30:03 [ERROR] zhenxun | 下载 ['https://i.pixiv.re/img-original/img/2022/12/30/21/04/18/104052603_p0.jpg'] 错误 Path：C:\Program Files\zhenxun\zhenxun_bot-dev\resources\temp\3.jpg || 错误 <class 'httpx.ConnectError'>: 
01-04 04:30:04 [ERROR] zhenxun | 下载 ['https://i.pixiv.re/img-original/img/2023/09/09/18/30/20/111577264_p0.png'] 错误 Path：C:\Program Files\zhenxun\zhenxun_bot-dev\resources\temp\2.jpg || 错误 <class 'httpx.ConnectError'>: 
01-04 04:30:05 [ERROR] zhenxun | 下载 ['https://i.pixiv.re/img-original/img/2023/01/01/17/17/43/104132686_p0.png'] 错误 Path：C:\Program Files\zhenxun\zhenxun_bot-dev\resources\temp\1.jpg || 错误 <class 'httpx.ConnectError'>: 
01-04 04:30:06 [ERROR] zhenxun | 下载 ['https://i.pixiv.re/img-original/img/2022/10/13/01/09/34/101889280_p0.png'] 错误 Path：C:\Program Files\zhenxun\zhenxun_bot-dev\resources\temp\0.jpg || 错误 <class 'httpx.ConnectError'>: 
01-04 04:30:07 [ERROR] zhenxun | 下载 ['https://i.pixiv.re/img-original/img/2022/01/28/15/00/34/95827678_p0.jpg'] 错误 Path：C:\Program Files\zhenxun\zhenxun_bot-dev\resources\temp\0.jpg || 错误 <class 'httpx.ConnectError'>: 
01-04 06:01:01 [ERROR] zhenxun | CMD[被动早晚安] [Target]([992333365:None]) 发送失败 || 错误 <class 'nonebot.adapters.onebot.v11.exception.ActionFailed'>: ActionFailed(status='failed', retcode=1200, data=None, message='Error: EventChecker Failed: NTEvent serviceAndMethod:NodeIKernelMsgService/sendMsg ListenerName:NodeIKernelMsgListener/onMsgInfoListUpdate EventRet:\n{\n    "result": 120,\n    "errMsg": ""\n}\n\n    at file:///C:/Users/Administrator/Documents/LiteloaderQQNT/plugins/NapCat.Framework/napcat.mjs:7704:15', wording='Error: EventChecker Failed: NTEvent serviceAndMethod:NodeIKernelMsgService/sendMsg ListenerName:NodeIKernelMsgListener/onMsgInfoListUpdate EventRet:\n{\n    "result": 120,\n    "errMsg": ""\n}\n\n    at file:///C:/Users/Administrator/Documents/LiteloaderQQNT/plugins/NapCat.Framework/napcat.mjs:7704:15', echo='2565')
01-04 09:01:01 [ERROR] zhenxun | CMD[被动每日新闻] [Target]([992333365:None]) 发送失败 || 错误 <class 'nonebot.adapters.onebot.v11.exception.ActionFailed'>: ActionFailed(status='failed', retcode=1200, data=None, message='Error: EventChecker Failed: NTEvent serviceAndMethod:NodeIKernelMsgService/sendMsg ListenerName:NodeIKernelMsgListener/onMsgInfoListUpdate EventRet:\n{\n    "result": 120,\n    "errMsg": ""\n}\n\n    at file:///C:/Users/Administrator/Documents/LiteloaderQQNT/plugins/NapCat.Framework/napcat.mjs:7704:15', wording='Error: EventChecker Failed: NTEvent serviceAndMethod:NodeIKernelMsgService/sendMsg ListenerName:NodeIKernelMsgListener/onMsgInfoListUpdate EventRet:\n{\n    "result": 120,\n    "errMsg": ""\n}\n\n    at file:///C:/Users/Administrator/Documents/LiteloaderQQNT/plugins/NapCat.Framework/napcat.mjs:7704:15', echo='2929')
01-04 09:01:02 [ERROR] apscheduler | Job "_ (trigger: cron[hour='9', minute='1'], next run at: 2025-01-05 09:01:00 CST)" raised an exception
Traceback (most recent call last):

  File "C:\Users\Administrator\AppData\Local\pypoetry\Cache\virtualenvs\zhenxun-bot-k9jvl_fX-py3.10\lib\site-packages\anyio\streams\tls.py", line 140, in _call_sslobject_method
    result = func(*args)
             │     └ ()
             └ <bound method SSLObject.do_handshake of <ssl.SSLObject object at 0x00000189411E8FA0>>

  File "C:\Users\Administrator\AppData\Local\Programs\Python\Python310\lib\ssl.py", line 975, in do_handshake
    self._sslobj.do_handshake()
    │    │       └ <method 'do_handshake' of '_ssl._SSLSocket' objects>
    │    └ <_ssl._SSLSocket object at 0x000001894509C6C0>
    └ <ssl.SSLObject object at 0x00000189411E8FA0>

ssl.SSLSyscallError: Some I/O error occurred (_ssl.c:1007)


The above exception was the direct cause of the following exception:


Traceback (most recent call last):

  File "C:\Users\Administrator\AppData\Local\pypoetry\Cache\virtualenvs\zhenxun-bot-k9jvl_fX-py3.10\lib\site-packages\httpcore\_exceptions.py", line 10, in map_exceptions
    yield

  File "C:\Users\Administrator\AppData\Local\pypoetry\Cache\virtualenvs\zhenxun-bot-k9jvl_fX-py3.10\lib\site-packages\httpcore\backends\asyncio.py", line 78, in start_tls
    raise exc

  File "C:\Users\Administrator\AppData\Local\pypoetry\Cache\virtualenvs\zhenxun-bot-k9jvl_fX-py3.10\lib\site-packages\httpcore\backends\asyncio.py", line 69, in start_tls
    ssl_stream = await anyio.streams.tls.TLSStream.wrap(
                       │     │       │   │         └ <classmethod(<function TLSStream.wrap at 0x000001892F45E950>)>
                       │     │       │   └ <class 'anyio.streams.tls.TLSStream'>
                       │     │       └ <module 'anyio.streams.tls' from 'C:\\Users\\Administrator\\AppData\\Local\\pypoetry\\Cache\\virtualenvs\\zhenxun-bot-k9jvl_f...
                       │     └ <module 'anyio.streams' from 'C:\\Users\\Administrator\\AppData\\Local\\pypoetry\\Cache\\virtualenvs\\zhenxun-bot-k9jvl_fX-py...
                       └ <module 'anyio' from 'C:\\Users\\Administrator\\AppData\\Local\\pypoetry\\Cache\\virtualenvs\\zhenxun-bot-k9jvl_fX-py3.10\\li...

  File "C:\Users\Administrator\AppData\Local\pypoetry\Cache\virtualenvs\zhenxun-bot-k9jvl_fX-py3.10\lib\site-packages\anyio\streams\tls.py", line 132, in wrap
    await wrapper._call_sslobject_method(ssl_object.do_handshake)
          │       │                      │          └ <function SSLObject.do_handshake at 0x000001892C914CA0>
          │       │                      └ <ssl.SSLObject object at 0x00000189411E8FA0>
          │       └ <function TLSStream._call_sslobject_method at 0x000001892F45E9E0>
          └ TLSStream(transport_stream=<anyio._backends._asyncio.SocketStream object at 0x00000189411EA740>, standard_compatible=False, _...

  File "C:\Users\Administrator\AppData\Local\pypoetry\Cache\virtualenvs\zhenxun-bot-k9jvl_fX-py3.10\lib\site-packages\anyio\streams\tls.py", line 161, in _call_sslobject_method
    raise BrokenResourceError from exc
          └ <class 'anyio.BrokenResourceError'>

anyio.BrokenResourceError


During handling of the above exception, another exception occurred:


Traceback (most recent call last):

  File "C:\Users\Administrator\AppData\Local\pypoetry\Cache\virtualenvs\zhenxun-bot-k9jvl_fX-py3.10\lib\site-packages\httpx\_transports\default.py", line 60, in map_httpcore_exceptions
    yield

  File "C:\Users\Administrator\AppData\Local\pypoetry\Cache\virtualenvs\zhenxun-bot-k9jvl_fX-py3.10\lib\site-packages\httpx\_transports\default.py", line 353, in handle_async_request
    resp = await self._pool.handle_async_request(req)
                 │    │     │                    └ <Request [b'GET']>
                 │    │     └ <function AsyncConnectionPool.handle_async_request at 0x00000189301CEA70>
                 │    └ <httpcore.AsyncHTTPProxy object at 0x0000018940A162C0>
                 └ <httpx.AsyncHTTPTransport object at 0x0000018940A158A0>

  File "C:\Users\Administrator\AppData\Local\pypoetry\Cache\virtualenvs\zhenxun-bot-k9jvl_fX-py3.10\lib\site-packages\httpcore\_async\connection_pool.py", line 253, in handle_async_request
    raise exc

  File "C:\Users\Administrator\AppData\Local\pypoetry\Cache\virtualenvs\zhenxun-bot-k9jvl_fX-py3.10\lib\site-packages\httpcore\_async\connection_pool.py", line 237, in handle_async_request
    response = await connection.handle_async_request(request)
                     │          │                    └ <Request [b'GET']>
                     │          └ <function AsyncTunnelHTTPConnection.handle_async_request at 0x00000189301CF7F0>
                     └ <AsyncTunnelHTTPConnection ['http://127.0.0.1:7890', HTTP/1.1, CLOSED, Request Count: 1]>

  File "C:\Users\Administrator\AppData\Local\pypoetry\Cache\virtualenvs\zhenxun-bot-k9jvl_fX-py3.10\lib\site-packages\httpcore\_async\http_proxy.py", line 289, in handle_async_request
    stream = await stream.start_tls(**kwargs)
                   │      │           └ {'ssl_context': <ssl.SSLContext object at 0x000001894509CA40>, 'server_hostname': 'api.bgm.tv', 'timeout': 30}
                   │      └ <function AsyncIOStream.start_tls at 0x000001893F8D0310>
                   └ <httpcore.backends.asyncio.AsyncIOStream object at 0x00000189411E9900>

  File "C:\Users\Administrator\AppData\Local\pypoetry\Cache\virtualenvs\zhenxun-bot-k9jvl_fX-py3.10\lib\site-packages\httpcore\backends\asyncio.py", line 66, in start_tls
    with map_exceptions(exc_map):
         │              └ {<class 'TimeoutError'>: <class 'httpcore.ConnectTimeout'>, <class 'anyio.BrokenResourceError'>: <class 'httpcore.ConnectErro...
         └ <function map_exceptions at 0x000001893015D900>

  File "C:\Users\Administrator\AppData\Local\Programs\Python\Python310\lib\contextlib.py", line 153, in __exit__
    self.gen.throw(typ, value, traceback)
    │    │   │     │    │      └ <traceback object at 0x000001893FD3F1C0>
    │    │   │     │    └ BrokenResourceError()
    │    │   │     └ <class 'anyio.BrokenResourceError'>
    │    │   └ <method 'throw' of 'generator' objects>
    │    └ <generator object map_exceptions at 0x000001894536AB90>
    └ <contextlib._GeneratorContextManager object at 0x00000189411EBA90>

  File "C:\Users\Administrator\AppData\Local\pypoetry\Cache\virtualenvs\zhenxun-bot-k9jvl_fX-py3.10\lib\site-packages\httpcore\_exceptions.py", line 14, in map_exceptions
    raise to_exc(exc)
          └ <class 'httpcore.ConnectError'>

httpcore.ConnectError


The above exception was the direct cause of the following exception:


Traceback (most recent call last):

  File "C:\Program Files\zhenxun\zhenxun_bot-dev\bot.py", line 27, in <module>
    nonebot.run()
    │       └ <function run at 0x000001892EB86290>
    └ <module 'nonebot' from 'C:\\Users\\Administrator\\AppData\\Local\\pypoetry\\Cache\\virtualenvs\\zhenxun-bot-k9jvl_fX-py3.10\\...

  File "C:\Users\Administrator\AppData\Local\pypoetry\Cache\virtualenvs\zhenxun-bot-k9jvl_fX-py3.10\lib\site-packages\nonebot\__init__.py", line 335, in run
    get_driver().run(*args, **kwargs)
    │                 │       └ {}
    │                 └ ()
    └ <function get_driver at 0x000001892EB860E0>

  File "C:\Users\Administrator\AppData\Local\pypoetry\Cache\virtualenvs\zhenxun-bot-k9jvl_fX-py3.10\lib\site-packages\nonebot\drivers\fastapi.py", line 186, in run
    uvicorn.run(
    │       └ <function run at 0x000001892F35BD00>
    └ <module 'uvicorn' from 'C:\\Users\\Administrator\\AppData\\Local\\pypoetry\\Cache\\virtualenvs\\zhenxun-bot-k9jvl_fX-py3.10\\...

  File "C:\Users\Administrator\AppData\Local\pypoetry\Cache\virtualenvs\zhenxun-bot-k9jvl_fX-py3.10\lib\site-packages\uvicorn\main.py", line 579, in run
    server.run()
    │      └ <function Server.run at 0x000001892F35B640>
    └ <uvicorn.server.Server object at 0x000001893EFF22F0>

  File "C:\Users\Administrator\AppData\Local\pypoetry\Cache\virtualenvs\zhenxun-bot-k9jvl_fX-py3.10\lib\site-packages\uvicorn\server.py", line 65, in run
    return asyncio.run(self.serve(sockets=sockets))
           │       │   │    │             └ None
           │       │   │    └ <function Server.serve at 0x000001892F35B6D0>
           │       │   └ <uvicorn.server.Server object at 0x000001893EFF22F0>
           │       └ <function run at 0x000001892C870E50>
           └ <module 'asyncio' from 'C:\\Users\\Administrator\\AppData\\Local\\Programs\\Python\\Python310\\lib\\asyncio\\__init__.py'>

  File "C:\Users\Administrator\AppData\Local\Programs\Python\Python310\lib\asyncio\runners.py", line 44, in run
    return loop.run_until_complete(main)
           │    │                  └ <coroutine object Server.serve at 0x00000189316A34C0>
           │    └ <function BaseEventLoop.run_until_complete at 0x000001892C970280>
           └ <ProactorEventLoop running=True closed=False debug=False>

  File "C:\Users\Administrator\AppData\Local\Programs\Python\Python310\lib\asyncio\base_events.py", line 636, in run_until_complete
    self.run_forever()
    │    └ <function ProactorEventLoop.run_forever at 0x000001892E5B1510>
    └ <ProactorEventLoop running=True closed=False debug=False>

  File "C:\Users\Administrator\AppData\Local\Programs\Python\Python310\lib\asyncio\windows_events.py", line 321, in run_forever
    super().run_forever()

  File "C:\Users\Administrator\AppData\Local\Programs\Python\Python310\lib\asyncio\base_events.py", line 603, in run_forever
    self._run_once()
    │    └ <function BaseEventLoop._run_once at 0x000001892C971CF0>
    └ <ProactorEventLoop running=True closed=False debug=False>

  File "C:\Users\Administrator\AppData\Local\Programs\Python\Python310\lib\asyncio\base_events.py", line 1909, in _run_once
    handle._run()
    │      └ <function Handle._run at 0x000001892C9209D0>
    └ <Handle <TaskStepMethWrapper object at 0x00000189452FD1E0>()>

  File "C:\Users\Administrator\AppData\Local\Programs\Python\Python310\lib\asyncio\events.py", line 80, in _run
    self._context.run(self._callback, *self._args)
    │    │            │    │           │    └ <member '_args' of 'Handle' objects>
    │    │            │    │           └ <Handle <TaskStepMethWrapper object at 0x00000189452FD1E0>()>
    │    │            │    └ <member '_callback' of 'Handle' objects>
    │    │            └ <Handle <TaskStepMethWrapper object at 0x00000189452FD1E0>()>
    │    └ <member '_context' of 'Handle' objects>
    └ <Handle <TaskStepMethWrapper object at 0x00000189452FD1E0>()>

> File "C:\Users\Administrator\AppData\Local\pypoetry\Cache\virtualenvs\zhenxun-bot-k9jvl_fX-py3.10\lib\site-packages\apscheduler\executors\base_py3.py", line 30, in run_coroutine_job
    retval = await job.func(*job.args, **job.kwargs)
                   │   │     │   │       │   └ <member 'kwargs' of 'Job' objects>
                   │   │     │   │       └ <Job (id=129c6c8e7e2448db83add56a4b3f469e name=_)>
                   │   │     │   └ <member 'args' of 'Job' objects>
                   │   │     └ <Job (id=129c6c8e7e2448db83add56a4b3f469e name=_)>
                   │   └ <member 'func' of 'Job' objects>
                   └ <Job (id=129c6c8e7e2448db83add56a4b3f469e name=_)>

  File "C:\Program Files\zhenxun\zhenxun_bot-dev\zhenxun\plugins\mahiro_report\__init__.py", line 107, in _
    await Report.get_report_image()
          │      └ <classmethod(<function Report.get_report_image at 0x0000018939572200>)>
          └ <class 'zhenxun.plugins.mahiro_report.data_source.Report'>

  File "C:\Program Files\zhenxun\zhenxun_bot-dev\zhenxun\plugins\mahiro_report\data_source.py", line 49, in get_report_image
    "data_anime": await cls.get_anime(),
                        │   └ <classmethod(<function Report.get_anime at 0x0000018939572E60>)>
                        └ <class 'zhenxun.plugins.mahiro_report.data_source.Report'>

  File "C:\Program Files\zhenxun\zhenxun_bot-dev\zhenxun\plugins\mahiro_report\data_source.py", line 135, in get_anime
    res = await AsyncHttpx.get(cls.anime_url)
                │          │   │   └ 'https://api.bgm.tv/calendar'
                │          │   └ <class 'zhenxun.plugins.mahiro_report.data_source.Report'>
                │          └ <classmethod(<function AsyncHttpx.get at 0x000001892FEA9F30>)>
                └ <class 'zhenxun.utils.http_utils.AsyncHttpx'>

  File "C:\Program Files\zhenxun\zhenxun_bot-dev\zhenxun\utils\http_utils.py", line 60, in get
    return await cls._get_first_successful(
                 │   └ <classmethod(<function AsyncHttpx._get_first_successful at 0x000001892FEA9E10>)>
                 └ <class 'zhenxun.utils.http_utils.AsyncHttpx'>

  File "C:\Program Files\zhenxun\zhenxun_bot-dev\zhenxun\utils\http_utils.py", line 86, in _get_first_successful
    raise last_exception or Exception("All URLs failed")
          └ ConnectError('')

  File "C:\Program Files\zhenxun\zhenxun_bot-dev\zhenxun\utils\http_utils.py", line 81, in _get_first_successful
    return await cls._get_single(url, **kwargs)
                 │   │           │      └ {'params': None, 'headers': None, 'cookies': None, 'verify': False, 'use_proxy': False, 'proxy': None, 'timeout': 30}
                 │   │           └ 'https://api.bgm.tv/calendar'
                 │   └ <classmethod(<function AsyncHttpx._get_single at 0x000001892FEA9FC0>)>
                 └ <class 'zhenxun.utils.http_utils.AsyncHttpx'>

  File "C:\Program Files\zhenxun\zhenxun_bot-dev\zhenxun\utils\http_utils.py", line 106, in _get_single
    return await client.get(
                 │      └ <function AsyncClient.get at 0x00000189301FB370>
                 └ <httpx.AsyncClient object at 0x00000189452FE110>

  File "C:\Users\Administrator\AppData\Local\pypoetry\Cache\virtualenvs\zhenxun-bot-k9jvl_fX-py3.10\lib\site-packages\httpx\_client.py", line 1757, in get
    return await self.request(
                 │    └ <function AsyncClient.request at 0x00000189301FAF80>
                 └ <httpx.AsyncClient object at 0x00000189452FE110>

  File "C:\Users\Administrator\AppData\Local\pypoetry\Cache\virtualenvs\zhenxun-bot-k9jvl_fX-py3.10\lib\site-packages\httpx\_client.py", line 1533, in request
    return await self.send(request, auth=auth, follow_redirects=follow_redirects)
                 │    │    │             │                      └ <httpx._client.UseClientDefault object at 0x00000189300658D0>
                 │    │    │             └ <httpx._client.UseClientDefault object at 0x00000189300658D0>
                 │    │    └ <Request('GET', 'https://api.bgm.tv/calendar')>
                 │    └ <function AsyncClient.send at 0x00000189301FB130>
                 └ <httpx.AsyncClient object at 0x00000189452FE110>

  File "C:\Users\Administrator\AppData\Local\pypoetry\Cache\virtualenvs\zhenxun-bot-k9jvl_fX-py3.10\lib\site-packages\httpx\_client.py", line 1620, in send
    response = await self._send_handling_auth(
                     │    └ <function AsyncClient._send_handling_auth at 0x00000189301FB1C0>
                     └ <httpx.AsyncClient object at 0x00000189452FE110>

  File "C:\Users\Administrator\AppData\Local\pypoetry\Cache\virtualenvs\zhenxun-bot-k9jvl_fX-py3.10\lib\site-packages\httpx\_client.py", line 1648, in _send_handling_auth
    response = await self._send_handling_redirects(
                     │    └ <function AsyncClient._send_handling_redirects at 0x00000189301FB250>
                     └ <httpx.AsyncClient object at 0x00000189452FE110>

  File "C:\Users\Administrator\AppData\Local\pypoetry\Cache\virtualenvs\zhenxun-bot-k9jvl_fX-py3.10\lib\site-packages\httpx\_client.py", line 1685, in _send_handling_redirects
    response = await self._send_single_request(request)
                     │    │                    └ <Request('GET', 'https://api.bgm.tv/calendar')>
                     │    └ <function AsyncClient._send_single_request at 0x00000189301FB2E0>
                     └ <httpx.AsyncClient object at 0x00000189452FE110>

  File "C:\Users\Administrator\AppData\Local\pypoetry\Cache\virtualenvs\zhenxun-bot-k9jvl_fX-py3.10\lib\site-packages\httpx\_client.py", line 1722, in _send_single_request
    response = await transport.handle_async_request(request)
                     │         │                    └ <Request('GET', 'https://api.bgm.tv/calendar')>
                     │         └ <function AsyncHTTPTransport.handle_async_request at 0x00000189301F88B0>
                     └ <httpx.AsyncHTTPTransport object at 0x0000018940A158A0>

  File "C:\Users\Administrator\AppData\Local\pypoetry\Cache\virtualenvs\zhenxun-bot-k9jvl_fX-py3.10\lib\site-packages\httpx\_transports\default.py", line 352, in handle_async_request
    with map_httpcore_exceptions():
         └ <function map_httpcore_exceptions at 0x000001893015C3A0>

  File "C:\Users\Administrator\AppData\Local\Programs\Python\Python310\lib\contextlib.py", line 153, in __exit__
    self.gen.throw(typ, value, traceback)
    │    │   │     │    │      └ <traceback object at 0x000001893FD7C6C0>
    │    │   │     │    └ ConnectError(BrokenResourceError())
    │    │   │     └ <class 'httpcore.ConnectError'>
    │    │   └ <method 'throw' of 'generator' objects>
    │    └ <generator object map_httpcore_exceptions at 0x000001894536A1F0>
    └ <contextlib._GeneratorContextManager object at 0x0000018940A16560>

  File "C:\Users\Administrator\AppData\Local\pypoetry\Cache\virtualenvs\zhenxun-bot-k9jvl_fX-py3.10\lib\site-packages\httpx\_transports\default.py", line 77, in map_httpcore_exceptions
    raise mapped_exc(message) from exc
          │          └ ''
          └ <class 'httpx.ConnectError'>

httpx.ConnectError
01-04 09:01:08 [ERROR] zhenxun | CMD[被动每日新闻] [Target]([992333365:None]) 发送失败 || 错误 <class 'nonebot.adapters.onebot.v11.exception.ActionFailed'>: ActionFailed(status='failed', retcode=1200, data=None, message='Error: EventChecker Failed: NTEvent serviceAndMethod:NodeIKernelMsgService/sendMsg ListenerName:NodeIKernelMsgListener/onMsgInfoListUpdate EventRet:\n{\n    "result": 120,\n    "errMsg": ""\n}\n\n    at file:///C:/Users/Administrator/Documents/LiteloaderQQNT/plugins/NapCat.Framework/napcat.mjs:7704:15', wording='Error: EventChecker Failed: NTEvent serviceAndMethod:NodeIKernelMsgService/sendMsg ListenerName:NodeIKernelMsgListener/onMsgInfoListUpdate EventRet:\n{\n    "result": 120,\n    "errMsg": ""\n}\n\n    at file:///C:/Users/Administrator/Documents/LiteloaderQQNT/plugins/NapCat.Framework/napcat.mjs:7704:15', echo='2933')
01-04 15:01:00 [ERROR] zhenxun | CMD[真寻日报] [Target]([992333365:None]) 发送失败 || 错误 <class 'nonebot.adapters.onebot.v11.exception.ActionFailed'>: ActionFailed(status='failed', retcode=1200, data=None, message='Error: EventChecker Failed: NTEvent serviceAndMethod:NodeIKernelMsgService/sendMsg ListenerName:NodeIKernelMsgListener/onMsgInfoListUpdate EventRet:\n{\n    "result": 120,\n    "errMsg": ""\n}\n\n    at file:///C:/Users/Administrator/Documents/LiteloaderQQNT/plugins/NapCat.Framework/napcat.mjs:7704:15', wording='Error: EventChecker Failed: NTEvent serviceAndMethod:NodeIKernelMsgService/sendMsg ListenerName:NodeIKernelMsgListener/onMsgInfoListUpdate EventRet:\n{\n    "result": 120,\n    "errMsg": ""\n}\n\n    at file:///C:/Users/Administrator/Documents/LiteloaderQQNT/plugins/NapCat.Framework/napcat.mjs:7704:15', echo='3793')
01-04 15:01:04 [ERROR] apscheduler | Job "_ (trigger: cron[hour='15', minute='1'], next run at: 2025-01-05 15:01:00 CST)" raised an exception
Traceback (most recent call last):

  File "C:\Users\Administrator\AppData\Local\pypoetry\Cache\virtualenvs\zhenxun-bot-k9jvl_fX-py3.10\lib\site-packages\anyio\streams\tls.py", line 140, in _call_sslobject_method
    result = func(*args)
             │     └ ()
             └ <bound method SSLObject.do_handshake of <ssl.SSLObject object at 0x000001893F860B20>>

  File "C:\Users\Administrator\AppData\Local\Programs\Python\Python310\lib\ssl.py", line 975, in do_handshake
    self._sslobj.do_handshake()
    │    │       └ <method 'do_handshake' of '_ssl._SSLSocket' objects>
    │    └ <_ssl._SSLSocket object at 0x00000189404A61C0>
    └ <ssl.SSLObject object at 0x000001893F860B20>

ssl.SSLSyscallError: Some I/O error occurred (_ssl.c:1007)


The above exception was the direct cause of the following exception:


Traceback (most recent call last):

  File "C:\Users\Administrator\AppData\Local\pypoetry\Cache\virtualenvs\zhenxun-bot-k9jvl_fX-py3.10\lib\site-packages\httpcore\_exceptions.py", line 10, in map_exceptions
    yield

  File "C:\Users\Administrator\AppData\Local\pypoetry\Cache\virtualenvs\zhenxun-bot-k9jvl_fX-py3.10\lib\site-packages\httpcore\backends\asyncio.py", line 78, in start_tls
    raise exc

  File "C:\Users\Administrator\AppData\Local\pypoetry\Cache\virtualenvs\zhenxun-bot-k9jvl_fX-py3.10\lib\site-packages\httpcore\backends\asyncio.py", line 69, in start_tls
    ssl_stream = await anyio.streams.tls.TLSStream.wrap(
                       │     │       │   │         └ <classmethod(<function TLSStream.wrap at 0x000001892F45E950>)>
                       │     │       │   └ <class 'anyio.streams.tls.TLSStream'>
                       │     │       └ <module 'anyio.streams.tls' from 'C:\\Users\\Administrator\\AppData\\Local\\pypoetry\\Cache\\virtualenvs\\zhenxun-bot-k9jvl_f...
                       │     └ <module 'anyio.streams' from 'C:\\Users\\Administrator\\AppData\\Local\\pypoetry\\Cache\\virtualenvs\\zhenxun-bot-k9jvl_fX-py...
                       └ <module 'anyio' from 'C:\\Users\\Administrator\\AppData\\Local\\pypoetry\\Cache\\virtualenvs\\zhenxun-bot-k9jvl_fX-py3.10\\li...

  File "C:\Users\Administrator\AppData\Local\pypoetry\Cache\virtualenvs\zhenxun-bot-k9jvl_fX-py3.10\lib\site-packages\anyio\streams\tls.py", line 132, in wrap
    await wrapper._call_sslobject_method(ssl_object.do_handshake)
          │       │                      │          └ <function SSLObject.do_handshake at 0x000001892C914CA0>
          │       │                      └ <ssl.SSLObject object at 0x000001893F860B20>
          │       └ <function TLSStream._call_sslobject_method at 0x000001892F45E9E0>
          └ TLSStream(transport_stream=<anyio._backends._asyncio.SocketStream object at 0x000001893F863F70>, standard_compatible=False, _...

  File "C:\Users\Administrator\AppData\Local\pypoetry\Cache\virtualenvs\zhenxun-bot-k9jvl_fX-py3.10\lib\site-packages\anyio\streams\tls.py", line 161, in _call_sslobject_method
    raise BrokenResourceError from exc
          └ <class 'anyio.BrokenResourceError'>

anyio.BrokenResourceError


During handling of the above exception, another exception occurred:


Traceback (most recent call last):

  File "C:\Users\Administrator\AppData\Local\pypoetry\Cache\virtualenvs\zhenxun-bot-k9jvl_fX-py3.10\lib\site-packages\httpx\_transports\default.py", line 60, in map_httpcore_exceptions
    yield

  File "C:\Users\Administrator\AppData\Local\pypoetry\Cache\virtualenvs\zhenxun-bot-k9jvl_fX-py3.10\lib\site-packages\httpx\_transports\default.py", line 353, in handle_async_request
    resp = await self._pool.handle_async_request(req)
                 │    │     │                    └ <Request [b'GET']>
                 │    │     └ <function AsyncConnectionPool.handle_async_request at 0x00000189301CEA70>
                 │    └ <httpcore.AsyncHTTPProxy object at 0x0000018940EDCB50>
                 └ <httpx.AsyncHTTPTransport object at 0x0000018940EDDF60>

  File "C:\Users\Administrator\AppData\Local\pypoetry\Cache\virtualenvs\zhenxun-bot-k9jvl_fX-py3.10\lib\site-packages\httpcore\_async\connection_pool.py", line 253, in handle_async_request
    raise exc

  File "C:\Users\Administrator\AppData\Local\pypoetry\Cache\virtualenvs\zhenxun-bot-k9jvl_fX-py3.10\lib\site-packages\httpcore\_async\connection_pool.py", line 237, in handle_async_request
    response = await connection.handle_async_request(request)
                     │          │                    └ <Request [b'GET']>
                     │          └ <function AsyncTunnelHTTPConnection.handle_async_request at 0x00000189301CF7F0>
                     └ <AsyncTunnelHTTPConnection ['http://127.0.0.1:7890', HTTP/1.1, CLOSED, Request Count: 1]>

  File "C:\Users\Administrator\AppData\Local\pypoetry\Cache\virtualenvs\zhenxun-bot-k9jvl_fX-py3.10\lib\site-packages\httpcore\_async\http_proxy.py", line 289, in handle_async_request
    stream = await stream.start_tls(**kwargs)
                   │      │           └ {'ssl_context': <ssl.SSLContext object at 0x000001893F8230C0>, 'server_hostname': 'api.bgm.tv', 'timeout': 30}
                   │      └ <function AsyncIOStream.start_tls at 0x000001893F8D0310>
                   └ <httpcore.backends.asyncio.AsyncIOStream object at 0x000001893F861360>

  File "C:\Users\Administrator\AppData\Local\pypoetry\Cache\virtualenvs\zhenxun-bot-k9jvl_fX-py3.10\lib\site-packages\httpcore\backends\asyncio.py", line 66, in start_tls
    with map_exceptions(exc_map):
         │              └ {<class 'TimeoutError'>: <class 'httpcore.ConnectTimeout'>, <class 'anyio.BrokenResourceError'>: <class 'httpcore.ConnectErro...
         └ <function map_exceptions at 0x000001893015D900>

  File "C:\Users\Administrator\AppData\Local\Programs\Python\Python310\lib\contextlib.py", line 153, in __exit__
    self.gen.throw(typ, value, traceback)
    │    │   │     │    │      └ <traceback object at 0x000001894104E240>
    │    │   │     │    └ BrokenResourceError()
    │    │   │     └ <class 'anyio.BrokenResourceError'>
    │    │   └ <method 'throw' of 'generator' objects>
    │    └ <generator object map_exceptions at 0x00000189411F7A70>
    └ <contextlib._GeneratorContextManager object at 0x000001893F862350>

  File "C:\Users\Administrator\AppData\Local\pypoetry\Cache\virtualenvs\zhenxun-bot-k9jvl_fX-py3.10\lib\site-packages\httpcore\_exceptions.py", line 14, in map_exceptions
    raise to_exc(exc)
          └ <class 'httpcore.ConnectError'>

httpcore.ConnectError


The above exception was the direct cause of the following exception:


Traceback (most recent call last):

  File "C:\Program Files\zhenxun\zhenxun_bot-dev\bot.py", line 27, in <module>
    nonebot.run()
    │       └ <function run at 0x000001892EB86290>
    └ <module 'nonebot' from 'C:\\Users\\Administrator\\AppData\\Local\\pypoetry\\Cache\\virtualenvs\\zhenxun-bot-k9jvl_fX-py3.10\\...

  File "C:\Users\Administrator\AppData\Local\pypoetry\Cache\virtualenvs\zhenxun-bot-k9jvl_fX-py3.10\lib\site-packages\nonebot\__init__.py", line 335, in run
    get_driver().run(*args, **kwargs)
    │                 │       └ {}
    │                 └ ()
    └ <function get_driver at 0x000001892EB860E0>

  File "C:\Users\Administrator\AppData\Local\pypoetry\Cache\virtualenvs\zhenxun-bot-k9jvl_fX-py3.10\lib\site-packages\nonebot\drivers\fastapi.py", line 186, in run
    uvicorn.run(
    │       └ <function run at 0x000001892F35BD00>
    └ <module 'uvicorn' from 'C:\\Users\\Administrator\\AppData\\Local\\pypoetry\\Cache\\virtualenvs\\zhenxun-bot-k9jvl_fX-py3.10\\...

  File "C:\Users\Administrator\AppData\Local\pypoetry\Cache\virtualenvs\zhenxun-bot-k9jvl_fX-py3.10\lib\site-packages\uvicorn\main.py", line 579, in run
    server.run()
    │      └ <function Server.run at 0x000001892F35B640>
    └ <uvicorn.server.Server object at 0x000001893EFF22F0>

  File "C:\Users\Administrator\AppData\Local\pypoetry\Cache\virtualenvs\zhenxun-bot-k9jvl_fX-py3.10\lib\site-packages\uvicorn\server.py", line 65, in run
    return asyncio.run(self.serve(sockets=sockets))
           │       │   │    │             └ None
           │       │   │    └ <function Server.serve at 0x000001892F35B6D0>
           │       │   └ <uvicorn.server.Server object at 0x000001893EFF22F0>
           │       └ <function run at 0x000001892C870E50>
           └ <module 'asyncio' from 'C:\\Users\\Administrator\\AppData\\Local\\Programs\\Python\\Python310\\lib\\asyncio\\__init__.py'>

  File "C:\Users\Administrator\AppData\Local\Programs\Python\Python310\lib\asyncio\runners.py", line 44, in run
    return loop.run_until_complete(main)
           │    │                  └ <coroutine object Server.serve at 0x00000189316A34C0>
           │    └ <function BaseEventLoop.run_until_complete at 0x000001892C970280>
           └ <ProactorEventLoop running=True closed=False debug=False>

  File "C:\Users\Administrator\AppData\Local\Programs\Python\Python310\lib\asyncio\base_events.py", line 636, in run_until_complete
    self.run_forever()
    │    └ <function ProactorEventLoop.run_forever at 0x000001892E5B1510>
    └ <ProactorEventLoop running=True closed=False debug=False>

  File "C:\Users\Administrator\AppData\Local\Programs\Python\Python310\lib\asyncio\windows_events.py", line 321, in run_forever
    super().run_forever()

  File "C:\Users\Administrator\AppData\Local\Programs\Python\Python310\lib\asyncio\base_events.py", line 603, in run_forever
    self._run_once()
    │    └ <function BaseEventLoop._run_once at 0x000001892C971CF0>
    └ <ProactorEventLoop running=True closed=False debug=False>

  File "C:\Users\Administrator\AppData\Local\Programs\Python\Python310\lib\asyncio\base_events.py", line 1909, in _run_once
    handle._run()
    │      └ <function Handle._run at 0x000001892C9209D0>
    └ <Handle <TaskStepMethWrapper object at 0x000001893F862890>()>

  File "C:\Users\Administrator\AppData\Local\Programs\Python\Python310\lib\asyncio\events.py", line 80, in _run
    self._context.run(self._callback, *self._args)
    │    │            │    │           │    └ <member '_args' of 'Handle' objects>
    │    │            │    │           └ <Handle <TaskStepMethWrapper object at 0x000001893F862890>()>
    │    │            │    └ <member '_callback' of 'Handle' objects>
    │    │            └ <Handle <TaskStepMethWrapper object at 0x000001893F862890>()>
    │    └ <member '_context' of 'Handle' objects>
    └ <Handle <TaskStepMethWrapper object at 0x000001893F862890>()>

> File "C:\Users\Administrator\AppData\Local\pypoetry\Cache\virtualenvs\zhenxun-bot-k9jvl_fX-py3.10\lib\site-packages\apscheduler\executors\base_py3.py", line 30, in run_coroutine_job
    retval = await job.func(*job.args, **job.kwargs)
                   │   │     │   │       │   └ <member 'kwargs' of 'Job' objects>
                   │   │     │   │       └ <Job (id=cc437ad42d824428aee9b9a431973176 name=_)>
                   │   │     │   └ <member 'args' of 'Job' objects>
                   │   │     └ <Job (id=cc437ad42d824428aee9b9a431973176 name=_)>
                   │   └ <member 'func' of 'Job' objects>
                   └ <Job (id=cc437ad42d824428aee9b9a431973176 name=_)>

  File "C:\Program Files\zhenxun\zhenxun_bot-dev\zhenxun\plugins\mahiro_report\__init__.py", line 122, in _
    file = await Report.get_report_image()
                 │      └ <classmethod(<function Report.get_report_image at 0x0000018939572200>)>
                 └ <class 'zhenxun.plugins.mahiro_report.data_source.Report'>

  File "C:\Program Files\zhenxun\zhenxun_bot-dev\zhenxun\plugins\mahiro_report\data_source.py", line 49, in get_report_image
    "data_anime": await cls.get_anime(),
                        │   └ <classmethod(<function Report.get_anime at 0x0000018939572E60>)>
                        └ <class 'zhenxun.plugins.mahiro_report.data_source.Report'>

  File "C:\Program Files\zhenxun\zhenxun_bot-dev\zhenxun\plugins\mahiro_report\data_source.py", line 135, in get_anime
    res = await AsyncHttpx.get(cls.anime_url)
                │          │   │   └ 'https://api.bgm.tv/calendar'
                │          │   └ <class 'zhenxun.plugins.mahiro_report.data_source.Report'>
                │          └ <classmethod(<function AsyncHttpx.get at 0x000001892FEA9F30>)>
                └ <class 'zhenxun.utils.http_utils.AsyncHttpx'>

  File "C:\Program Files\zhenxun\zhenxun_bot-dev\zhenxun\utils\http_utils.py", line 60, in get
    return await cls._get_first_successful(
                 │   └ <classmethod(<function AsyncHttpx._get_first_successful at 0x000001892FEA9E10>)>
                 └ <class 'zhenxun.utils.http_utils.AsyncHttpx'>

  File "C:\Program Files\zhenxun\zhenxun_bot-dev\zhenxun\utils\http_utils.py", line 86, in _get_first_successful
    raise last_exception or Exception("All URLs failed")
          └ ConnectError('')

  File "C:\Program Files\zhenxun\zhenxun_bot-dev\zhenxun\utils\http_utils.py", line 81, in _get_first_successful
    return await cls._get_single(url, **kwargs)
                 │   │           │      └ {'params': None, 'headers': None, 'cookies': None, 'verify': False, 'use_proxy': False, 'proxy': None, 'timeout': 30}
                 │   │           └ 'https://api.bgm.tv/calendar'
                 │   └ <classmethod(<function AsyncHttpx._get_single at 0x000001892FEA9FC0>)>
                 └ <class 'zhenxun.utils.http_utils.AsyncHttpx'>

  File "C:\Program Files\zhenxun\zhenxun_bot-dev\zhenxun\utils\http_utils.py", line 106, in _get_single
    return await client.get(
                 │      └ <function AsyncClient.get at 0x00000189301FB370>
                 └ <httpx.AsyncClient object at 0x0000018940D96B90>

  File "C:\Users\Administrator\AppData\Local\pypoetry\Cache\virtualenvs\zhenxun-bot-k9jvl_fX-py3.10\lib\site-packages\httpx\_client.py", line 1757, in get
    return await self.request(
                 │    └ <function AsyncClient.request at 0x00000189301FAF80>
                 └ <httpx.AsyncClient object at 0x0000018940D96B90>

  File "C:\Users\Administrator\AppData\Local\pypoetry\Cache\virtualenvs\zhenxun-bot-k9jvl_fX-py3.10\lib\site-packages\httpx\_client.py", line 1533, in request
    return await self.send(request, auth=auth, follow_redirects=follow_redirects)
                 │    │    │             │                      └ <httpx._client.UseClientDefault object at 0x00000189300658D0>
                 │    │    │             └ <httpx._client.UseClientDefault object at 0x00000189300658D0>
                 │    │    └ <Request('GET', 'https://api.bgm.tv/calendar')>
                 │    └ <function AsyncClient.send at 0x00000189301FB130>
                 └ <httpx.AsyncClient object at 0x0000018940D96B90>

  File "C:\Users\Administrator\AppData\Local\pypoetry\Cache\virtualenvs\zhenxun-bot-k9jvl_fX-py3.10\lib\site-packages\httpx\_client.py", line 1620, in send
    response = await self._send_handling_auth(
                     │    └ <function AsyncClient._send_handling_auth at 0x00000189301FB1C0>
                     └ <httpx.AsyncClient object at 0x0000018940D96B90>

  File "C:\Users\Administrator\AppData\Local\pypoetry\Cache\virtualenvs\zhenxun-bot-k9jvl_fX-py3.10\lib\site-packages\httpx\_client.py", line 1648, in _send_handling_auth
    response = await self._send_handling_redirects(
                     │    └ <function AsyncClient._send_handling_redirects at 0x00000189301FB250>
                     └ <httpx.AsyncClient object at 0x0000018940D96B90>

  File "C:\Users\Administrator\AppData\Local\pypoetry\Cache\virtualenvs\zhenxun-bot-k9jvl_fX-py3.10\lib\site-packages\httpx\_client.py", line 1685, in _send_handling_redirects
    response = await self._send_single_request(request)
                     │    │                    └ <Request('GET', 'https://api.bgm.tv/calendar')>
                     │    └ <function AsyncClient._send_single_request at 0x00000189301FB2E0>
                     └ <httpx.AsyncClient object at 0x0000018940D96B90>

  File "C:\Users\Administrator\AppData\Local\pypoetry\Cache\virtualenvs\zhenxun-bot-k9jvl_fX-py3.10\lib\site-packages\httpx\_client.py", line 1722, in _send_single_request
    response = await transport.handle_async_request(request)
                     │         │                    └ <Request('GET', 'https://api.bgm.tv/calendar')>
                     │         └ <function AsyncHTTPTransport.handle_async_request at 0x00000189301F88B0>
                     └ <httpx.AsyncHTTPTransport object at 0x0000018940EDDF60>

  File "C:\Users\Administrator\AppData\Local\pypoetry\Cache\virtualenvs\zhenxun-bot-k9jvl_fX-py3.10\lib\site-packages\httpx\_transports\default.py", line 352, in handle_async_request
    with map_httpcore_exceptions():
         └ <function map_httpcore_exceptions at 0x000001893015C3A0>

  File "C:\Users\Administrator\AppData\Local\Programs\Python\Python310\lib\contextlib.py", line 153, in __exit__
    self.gen.throw(typ, value, traceback)
    │    │   │     │    │      └ <traceback object at 0x0000018944E36CC0>
    │    │   │     │    └ ConnectError(BrokenResourceError())
    │    │   │     └ <class 'httpcore.ConnectError'>
    │    │   └ <method 'throw' of 'generator' objects>
    │    └ <generator object map_httpcore_exceptions at 0x000001894536B1B0>
    └ <contextlib._GeneratorContextManager object at 0x000001893F8624D0>

  File "C:\Users\Administrator\AppData\Local\pypoetry\Cache\virtualenvs\zhenxun-bot-k9jvl_fX-py3.10\lib\site-packages\httpx\_transports\default.py", line 77, in map_httpcore_exceptions
    raise mapped_exc(message) from exc
          │          └ ''
          └ <class 'httpx.ConnectError'>

httpx.ConnectError
01-04 15:39:53 [ERROR] nonebot | Running Matcher(type='message', module=zhenxun.plugins.parse_bilibili, lineno=54) failed.
Traceback (most recent call last):

  File "C:\Program Files\zhenxun\zhenxun_bot-dev\bot.py", line 27, in <module>
    nonebot.run()
    │       └ <function run at 0x000001892EB86290>
    └ <module 'nonebot' from 'C:\\Users\\Administrator\\AppData\\Local\\pypoetry\\Cache\\virtualenvs\\zhenxun-bot-k9jvl_fX-py3.10\\...

  File "C:\Users\Administrator\AppData\Local\pypoetry\Cache\virtualenvs\zhenxun-bot-k9jvl_fX-py3.10\lib\site-packages\nonebot\__init__.py", line 335, in run
    get_driver().run(*args, **kwargs)
    │                 │       └ {}
    │                 └ ()
    └ <function get_driver at 0x000001892EB860E0>

  File "C:\Users\Administrator\AppData\Local\pypoetry\Cache\virtualenvs\zhenxun-bot-k9jvl_fX-py3.10\lib\site-packages\nonebot\drivers\fastapi.py", line 186, in run
    uvicorn.run(
    │       └ <function run at 0x000001892F35BD00>
    └ <module 'uvicorn' from 'C:\\Users\\Administrator\\AppData\\Local\\pypoetry\\Cache\\virtualenvs\\zhenxun-bot-k9jvl_fX-py3.10\\...

  File "C:\Users\Administrator\AppData\Local\pypoetry\Cache\virtualenvs\zhenxun-bot-k9jvl_fX-py3.10\lib\site-packages\uvicorn\main.py", line 579, in run
    server.run()
    │      └ <function Server.run at 0x000001892F35B640>
    └ <uvicorn.server.Server object at 0x000001893EFF22F0>

  File "C:\Users\Administrator\AppData\Local\pypoetry\Cache\virtualenvs\zhenxun-bot-k9jvl_fX-py3.10\lib\site-packages\uvicorn\server.py", line 65, in run
    return asyncio.run(self.serve(sockets=sockets))
           │       │   │    │             └ None
           │       │   │    └ <function Server.serve at 0x000001892F35B6D0>
           │       │   └ <uvicorn.server.Server object at 0x000001893EFF22F0>
           │       └ <function run at 0x000001892C870E50>
           └ <module 'asyncio' from 'C:\\Users\\Administrator\\AppData\\Local\\Programs\\Python\\Python310\\lib\\asyncio\\__init__.py'>

  File "C:\Users\Administrator\AppData\Local\Programs\Python\Python310\lib\asyncio\runners.py", line 44, in run
    return loop.run_until_complete(main)
           │    │                  └ <coroutine object Server.serve at 0x00000189316A34C0>
           │    └ <function BaseEventLoop.run_until_complete at 0x000001892C970280>
           └ <ProactorEventLoop running=True closed=False debug=False>

  File "C:\Users\Administrator\AppData\Local\Programs\Python\Python310\lib\asyncio\base_events.py", line 636, in run_until_complete
    self.run_forever()
    │    └ <function ProactorEventLoop.run_forever at 0x000001892E5B1510>
    └ <ProactorEventLoop running=True closed=False debug=False>

  File "C:\Users\Administrator\AppData\Local\Programs\Python\Python310\lib\asyncio\windows_events.py", line 321, in run_forever
    super().run_forever()

  File "C:\Users\Administrator\AppData\Local\Programs\Python\Python310\lib\asyncio\base_events.py", line 603, in run_forever
    self._run_once()
    │    └ <function BaseEventLoop._run_once at 0x000001892C971CF0>
    └ <ProactorEventLoop running=True closed=False debug=False>

  File "C:\Users\Administrator\AppData\Local\Programs\Python\Python310\lib\asyncio\base_events.py", line 1909, in _run_once
    handle._run()
    │      └ <function Handle._run at 0x000001892C9209D0>
    └ <Handle Task.task_wakeup(<_GatheringFu...b84581b'}})]]>)>

  File "C:\Users\Administrator\AppData\Local\Programs\Python\Python310\lib\asyncio\events.py", line 80, in _run
    self._context.run(self._callback, *self._args)
    │    │            │    │           │    └ <member '_args' of 'Handle' objects>
    │    │            │    │           └ <Handle Task.task_wakeup(<_GatheringFu...b84581b'}})]]>)>
    │    │            │    └ <member '_callback' of 'Handle' objects>
    │    │            └ <Handle Task.task_wakeup(<_GatheringFu...b84581b'}})]]>)>
    │    └ <member '_context' of 'Handle' objects>
    └ <Handle Task.task_wakeup(<_GatheringFu...b84581b'}})]]>)>

  File "C:\Users\Administrator\AppData\Local\pypoetry\Cache\virtualenvs\zhenxun-bot-k9jvl_fX-py3.10\lib\site-packages\nonebot\message.py", line 476, in check_and_run_matcher
    await _run_matcher(
          └ <function _run_matcher at 0x000001892ECD5750>

> File "C:\Users\Administrator\AppData\Local\pypoetry\Cache\virtualenvs\zhenxun-bot-k9jvl_fX-py3.10\lib\site-packages\nonebot\message.py", line 428, in _run_matcher
    await matcher.run(bot, event, state, stack, dependency_cache)
          │       │   │    │      │      │      └ {<function _event_to_me at 0x000001892EBE6A70>: <Task finished name='Task-4725082' coro=<_event_to_me() done, defined at C:\U...
          │       │   │    │      │      └ <contextlib.AsyncExitStack object at 0x00000189411FEC50>
          │       │   │    │      └ {'_prefix': {'command': None, 'raw_command': None, 'command_arg': None, 'command_start': None, 'command_whitespace': None}}
          │       │   │    └ PrivateMessageEvent(time=1735976393, self_id=3973508735, post_type='message', sub_type='friend', user_id=2747277822, message_...
          │       │   └ Bot(type='OneBot V11', self_id='3973508735')
          │       └ <function Matcher.run at 0x000001892EBE68C0>
          └ Matcher(type='message', module=zhenxun.plugins.parse_bilibili, lineno=54)

  File "C:\Users\Administrator\AppData\Local\pypoetry\Cache\virtualenvs\zhenxun-bot-k9jvl_fX-py3.10\lib\site-packages\nonebot\internal\matcher\matcher.py", line 850, in run
    await self.simple_run(bot, event, state, stack, dependency_cache)
          │    │          │    │      │      │      └ {<function _event_to_me at 0x000001892EBE6A70>: <Task finished name='Task-4725082' coro=<_event_to_me() done, defined at C:\U...
          │    │          │    │      │      └ <contextlib.AsyncExitStack object at 0x00000189411FEC50>
          │    │          │    │      └ {'_prefix': {'command': None, 'raw_command': None, 'command_arg': None, 'command_start': None, 'command_whitespace': None}}
          │    │          │    └ PrivateMessageEvent(time=1735976393, self_id=3973508735, post_type='message', sub_type='friend', user_id=2747277822, message_...
          │    │          └ Bot(type='OneBot V11', self_id='3973508735')
          │    └ <function Matcher.simple_run at 0x000001892EBE6830>
          └ Matcher(type='message', module=zhenxun.plugins.parse_bilibili, lineno=54)

  File "C:\Users\Administrator\AppData\Local\pypoetry\Cache\virtualenvs\zhenxun-bot-k9jvl_fX-py3.10\lib\site-packages\nonebot\internal\matcher\matcher.py", line 825, in simple_run
    await handler(
          └ Dependent(call=_)

  File "C:\Users\Administrator\AppData\Local\pypoetry\Cache\virtualenvs\zhenxun-bot-k9jvl_fX-py3.10\lib\site-packages\nonebot\dependencies\__init__.py", line 94, in __call__
    return await cast(Callable[..., Awaitable[R]], self.call)(**values)
                 │    │             │         │    │    │       └ {'session': Session(bot_id='3973508735', bot_type='OneBot V11', platform='qq', level=<SessionLevel.LEVEL1: 1>, id1='274727782...
                 │    │             │         │    │    └ <function _ at 0x000001893ED008B0>
                 │    │             │         │    └ Dependent(call=_)
                 │    │             │         └ ~R
                 │    │             └ <class 'collections.abc.Awaitable'>
                 │    └ typing.Callable
                 └ <function cast at 0x000001892C7004C0>

  File "C:\Program Files\zhenxun\zhenxun_bot-dev\zhenxun\plugins\parse_bilibili\__init__.py", line 86, in _
    get_url = (qqdocurl_value if qqdocurl_value else jumpUrl_value).split("?")[
               │                 │                   └ {}
               │                 └ {}
               └ {}

AttributeError: 'dict' object has no attribute 'split'
01-04 15:40:03 [ERROR] nonebot | Running Matcher(type='message', module=zhenxun.plugins.nonebot_plugin_sparkapi.matchers.block_private, lineno=11) failed.
Traceback (most recent call last):

  File "C:\Program Files\zhenxun\zhenxun_bot-dev\bot.py", line 27, in <module>
    nonebot.run()
    │       └ <function run at 0x000001892EB86290>
    └ <module 'nonebot' from 'C:\\Users\\Administrator\\AppData\\Local\\pypoetry\\Cache\\virtualenvs\\zhenxun-bot-k9jvl_fX-py3.10\\...

  File "C:\Users\Administrator\AppData\Local\pypoetry\Cache\virtualenvs\zhenxun-bot-k9jvl_fX-py3.10\lib\site-packages\nonebot\__init__.py", line 335, in run
    get_driver().run(*args, **kwargs)
    │                 │       └ {}
    │                 └ ()
    └ <function get_driver at 0x000001892EB860E0>

  File "C:\Users\Administrator\AppData\Local\pypoetry\Cache\virtualenvs\zhenxun-bot-k9jvl_fX-py3.10\lib\site-packages\nonebot\drivers\fastapi.py", line 186, in run
    uvicorn.run(
    │       └ <function run at 0x000001892F35BD00>
    └ <module 'uvicorn' from 'C:\\Users\\Administrator\\AppData\\Local\\pypoetry\\Cache\\virtualenvs\\zhenxun-bot-k9jvl_fX-py3.10\\...

  File "C:\Users\Administrator\AppData\Local\pypoetry\Cache\virtualenvs\zhenxun-bot-k9jvl_fX-py3.10\lib\site-packages\uvicorn\main.py", line 579, in run
    server.run()
    │      └ <function Server.run at 0x000001892F35B640>
    └ <uvicorn.server.Server object at 0x000001893EFF22F0>

  File "C:\Users\Administrator\AppData\Local\pypoetry\Cache\virtualenvs\zhenxun-bot-k9jvl_fX-py3.10\lib\site-packages\uvicorn\server.py", line 65, in run
    return asyncio.run(self.serve(sockets=sockets))
           │       │   │    │             └ None
           │       │   │    └ <function Server.serve at 0x000001892F35B6D0>
           │       │   └ <uvicorn.server.Server object at 0x000001893EFF22F0>
           │       └ <function run at 0x000001892C870E50>
           └ <module 'asyncio' from 'C:\\Users\\Administrator\\AppData\\Local\\Programs\\Python\\Python310\\lib\\asyncio\\__init__.py'>

  File "C:\Users\Administrator\AppData\Local\Programs\Python\Python310\lib\asyncio\runners.py", line 44, in run
    return loop.run_until_complete(main)
           │    │                  └ <coroutine object Server.serve at 0x00000189316A34C0>
           │    └ <function BaseEventLoop.run_until_complete at 0x000001892C970280>
           └ <ProactorEventLoop running=True closed=False debug=False>

  File "C:\Users\Administrator\AppData\Local\Programs\Python\Python310\lib\asyncio\base_events.py", line 636, in run_until_complete
    self.run_forever()
    │    └ <function ProactorEventLoop.run_forever at 0x000001892E5B1510>
    └ <ProactorEventLoop running=True closed=False debug=False>

  File "C:\Users\Administrator\AppData\Local\Programs\Python\Python310\lib\asyncio\windows_events.py", line 321, in run_forever
    super().run_forever()

  File "C:\Users\Administrator\AppData\Local\Programs\Python\Python310\lib\asyncio\base_events.py", line 603, in run_forever
    self._run_once()
    │    └ <function BaseEventLoop._run_once at 0x000001892C971CF0>
    └ <ProactorEventLoop running=True closed=False debug=False>

  File "C:\Users\Administrator\AppData\Local\Programs\Python\Python310\lib\asyncio\base_events.py", line 1909, in _run_once
    handle._run()
    │      └ <function Handle._run at 0x000001892C9209D0>
    └ <Handle Task.task_wakeup(<_GatheringFu...result=[None]>)>

  File "C:\Users\Administrator\AppData\Local\Programs\Python\Python310\lib\asyncio\events.py", line 80, in _run
    self._context.run(self._callback, *self._args)
    │    │            │    │           │    └ <member '_args' of 'Handle' objects>
    │    │            │    │           └ <Handle Task.task_wakeup(<_GatheringFu...result=[None]>)>
    │    │            │    └ <member '_callback' of 'Handle' objects>
    │    │            └ <Handle Task.task_wakeup(<_GatheringFu...result=[None]>)>
    │    └ <member '_context' of 'Handle' objects>
    └ <Handle Task.task_wakeup(<_GatheringFu...result=[None]>)>

  File "C:\Users\Administrator\AppData\Local\pypoetry\Cache\virtualenvs\zhenxun-bot-k9jvl_fX-py3.10\lib\site-packages\nonebot\message.py", line 476, in check_and_run_matcher
    await _run_matcher(
          └ <function _run_matcher at 0x000001892ECD5750>

> File "C:\Users\Administrator\AppData\Local\pypoetry\Cache\virtualenvs\zhenxun-bot-k9jvl_fX-py3.10\lib\site-packages\nonebot\message.py", line 428, in _run_matcher
    await matcher.run(bot, event, state, stack, dependency_cache)
          │       │   │    │      │      │      └ {<function _event_to_me at 0x000001892EBE6A70>: <Task finished name='Task-4725082' coro=<_event_to_me() done, defined at C:\U...
          │       │   │    │      │      └ <contextlib.AsyncExitStack object at 0x00000189411FEC50>
          │       │   │    │      └ {'_prefix': {'command': None, 'raw_command': None, 'command_arg': None, 'command_start': None, 'command_whitespace': None}}
          │       │   │    └ PrivateMessageEvent(time=1735976393, self_id=3973508735, post_type='message', sub_type='friend', user_id=2747277822, message_...
          │       │   └ Bot(type='OneBot V11', self_id='3973508735')
          │       └ <function Matcher.run at 0x000001892EBE68C0>
          └ Matcher(type='message', module=zhenxun.plugins.nonebot_plugin_sparkapi.matchers.block_private, lineno=11)

  File "C:\Users\Administrator\AppData\Local\pypoetry\Cache\virtualenvs\zhenxun-bot-k9jvl_fX-py3.10\lib\site-packages\nonebot\internal\matcher\matcher.py", line 850, in run
    await self.simple_run(bot, event, state, stack, dependency_cache)
          │    │          │    │      │      │      └ {<function _event_to_me at 0x000001892EBE6A70>: <Task finished name='Task-4725082' coro=<_event_to_me() done, defined at C:\U...
          │    │          │    │      │      └ <contextlib.AsyncExitStack object at 0x00000189411FEC50>
          │    │          │    │      └ {'_prefix': {'command': None, 'raw_command': None, 'command_arg': None, 'command_start': None, 'command_whitespace': None}}
          │    │          │    └ PrivateMessageEvent(time=1735976393, self_id=3973508735, post_type='message', sub_type='friend', user_id=2747277822, message_...
          │    │          └ Bot(type='OneBot V11', self_id='3973508735')
          │    └ <function Matcher.simple_run at 0x000001892EBE6830>
          └ Matcher(type='message', module=zhenxun.plugins.nonebot_plugin_sparkapi.matchers.block_private, lineno=11)

  File "C:\Users\Administrator\AppData\Local\pypoetry\Cache\virtualenvs\zhenxun-bot-k9jvl_fX-py3.10\lib\site-packages\nonebot\internal\matcher\matcher.py", line 825, in simple_run
    await handler(
          └ Dependent(call=_)

  File "C:\Users\Administrator\AppData\Local\pypoetry\Cache\virtualenvs\zhenxun-bot-k9jvl_fX-py3.10\lib\site-packages\nonebot\dependencies\__init__.py", line 94, in __call__
    return await cast(Callable[..., Awaitable[R]], self.call)(**values)
                 │    │             │         │    │    │       └ {}
                 │    │             │         │    │    └ <function _ at 0x000001893EC84D30>
                 │    │             │         │    └ Dependent(call=_)
                 │    │             │         └ ~R
                 │    │             └ <class 'collections.abc.Awaitable'>
                 │    └ typing.Callable
                 └ <function cast at 0x000001892C7004C0>

  File "C:\Program Files\zhenxun\zhenxun_bot-dev\zhenxun\plugins\nonebot_plugin_sparkapi\matchers\block_private.py", line 18, in _
    await matcher_blockprivate.finish("私聊功能已关闭！如有需要，请联系管理员。")
          │                    └ <classmethod(<function Matcher.finish at 0x000001892EBE5D80>)>
          └ Matcher(type='message', module=zhenxun.plugins.nonebot_plugin_sparkapi.matchers.block_private, lineno=11)

  File "C:\Users\Administrator\AppData\Local\pypoetry\Cache\virtualenvs\zhenxun-bot-k9jvl_fX-py3.10\lib\site-packages\nonebot\internal\matcher\matcher.py", line 582, in finish
    await cls.send(message, **kwargs)
          │   │    │          └ {}
          │   │    └ '私聊功能已关闭！如有需要，请联系管理员。'
          │   └ <classmethod(<function Matcher.send at 0x000001892EBE5CF0>)>
          └ Matcher(type='message', module=zhenxun.plugins.nonebot_plugin_sparkapi.matchers.block_private, lineno=11)

  File "C:\Users\Administrator\AppData\Local\pypoetry\Cache\virtualenvs\zhenxun-bot-k9jvl_fX-py3.10\lib\site-packages\nonebot\internal\matcher\matcher.py", line 566, in send
    return await bot.send(event=event, message=_message, **kwargs)
                 │   │          │              │           └ {}
                 │   │          │              └ '私聊功能已关闭！如有需要，请联系管理员。'
                 │   │          └ PrivateMessageEvent(time=1735976393, self_id=3973508735, post_type='message', sub_type='friend', user_id=2747277822, message_...
                 │   └ <function Bot.send at 0x000001892F0E4EE0>
                 └ Bot(type='OneBot V11', self_id='3973508735')

  File "C:\Users\Administrator\AppData\Local\pypoetry\Cache\virtualenvs\zhenxun-bot-k9jvl_fX-py3.10\lib\site-packages\nonebot\adapters\onebot\v11\bot.py", line 237, in send
    return await self.__class__.send_handler(self, event, message, **kwargs)
                 │    │                      │     │      │          └ {}
                 │    │                      │     │      └ '私聊功能已关闭！如有需要，请联系管理员。'
                 │    │                      │     └ PrivateMessageEvent(time=1735976393, self_id=3973508735, post_type='message', sub_type='friend', user_id=2747277822, message_...
                 │    │                      └ Bot(type='OneBot V11', self_id='3973508735')
                 │    └ <attribute '__class__' of 'object' objects>
                 └ Bot(type='OneBot V11', self_id='3973508735')

  File "C:\Users\Administrator\AppData\Local\pypoetry\Cache\virtualenvs\zhenxun-bot-k9jvl_fX-py3.10\lib\site-packages\nonebot\adapters\onebot\v11\bot.py", line 190, in send
    return await bot.send_msg(**params)
                 │              └ {'user_id': 2747277822, 'message_type': 'private', 'message': [MessageSegment(type='text', data={'text': '私聊功能已关闭！如有需要，请联系管理员...
                 └ Bot(type='OneBot V11', self_id='3973508735')

  File "C:\Users\Administrator\AppData\Local\pypoetry\Cache\virtualenvs\zhenxun-bot-k9jvl_fX-py3.10\lib\site-packages\nonebot\internal\adapter\bot.py", line 122, in call_api
    raise exception
          └ ActionFailed(status='failed', retcode=1200, data=None, message='Error: Timeout: NTEvent serviceAndMethod:NodeIKernelMsgServic...

  File "C:\Users\Administrator\AppData\Local\pypoetry\Cache\virtualenvs\zhenxun-bot-k9jvl_fX-py3.10\lib\site-packages\nonebot\internal\adapter\bot.py", line 97, in call_api
    result = await self.adapter._call_api(self, api, **data)
                   │    │       │         │     │      └ {'user_id': 2747277822, 'message_type': 'private', 'message': [MessageSegment(type='text', data={'text': '私聊功能已关闭！如有需要，请联系管理员...
                   │    │       │         │     └ 'send_msg'
                   │    │       │         └ Bot(type='OneBot V11', self_id='3973508735')
                   │    │       └ <function Adapter._call_api at 0x000001892C3E8820>
                   │    └ Adapter(name='OneBot V11')
                   └ Bot(type='OneBot V11', self_id='3973508735')

  File "C:\Users\Administrator\AppData\Local\pypoetry\Cache\virtualenvs\zhenxun-bot-k9jvl_fX-py3.10\lib\site-packages\nonebot\adapters\onebot\v11\adapter.py", line 147, in _call_api
    return handle_api_result(await self._result_store.fetch(seq, timeout))
           │                       │    │             │     │    └ 30.0
           │                       │    │             │     └ 3877
           │                       │    │             └ <function ResultStore.fetch at 0x000001892F0E6050>
           │                       │    └ <nonebot.adapters.onebot.store.ResultStore object at 0x000001892EDDD960>
           │                       └ Adapter(name='OneBot V11')
           └ <function handle_api_result at 0x000001892F079000>

  File "C:\Users\Administrator\AppData\Local\pypoetry\Cache\virtualenvs\zhenxun-bot-k9jvl_fX-py3.10\lib\site-packages\nonebot\adapters\onebot\v11\utils.py", line 58, in handle_api_result
    raise ActionFailed(**result)
          │              └ {'status': 'failed', 'retcode': 1200, 'data': None, 'message': 'Error: Timeout: NTEvent serviceAndMethod:NodeIKernelMsgServic...
          └ <class 'nonebot.adapters.onebot.v11.exception.ActionFailed'>

nonebot.adapters.onebot.v11.exception.ActionFailed: ActionFailed(status='failed', retcode=1200, data=None, message='Error: Timeout: NTEvent serviceAndMethod:NodeIKernelMsgService/sendMsg ListenerName:NodeIKernelMsgListener/onMsgInfoListUpdate EventRet:\n{}\n\n    at Timeout.sendDataCallback [as _onTimeout] (file:///C:/Users/Administrator/Documents/LiteloaderQQNT/plugins/NapCat.Framework/napcat.mjs:7666:15)\n    at listOnTimeout (node:internal/timers:573:17)\n    at process.processTimers (node:internal/timers:514:7)', wording='Error: Timeout: NTEvent serviceAndMethod:NodeIKernelMsgService/sendMsg ListenerName:NodeIKernelMsgListener/onMsgInfoListUpdate EventRet:\n{}\n\n    at Timeout.sendDataCallback [as _onTimeout] (file:///C:/Users/Administrator/Documents/LiteloaderQQNT/plugins/NapCat.Framework/napcat.mjs:7666:15)\n    at listOnTimeout (node:internal/timers:573:17)\n    at process.processTimers (node:internal/timers:514:7)', echo='3877')
01-04 18:01:01 [ERROR] zhenxun | CMD[被动查询微博热搜] [Target]([992333365:None]) 发送失败 || 错误 <class 'nonebot.adapters.onebot.v11.exception.ActionFailed'>: ActionFailed(status='failed', retcode=1200, data=None, message='Error: EventChecker Failed: NTEvent serviceAndMethod:NodeIKernelMsgService/sendMsg ListenerName:NodeIKernelMsgListener/onMsgInfoListUpdate EventRet:\n{\n    "result": 120,\n    "errMsg": ""\n}\n\n    at file:///C:/Users/Administrator/Documents/LiteloaderQQNT/plugins/NapCat.Framework/napcat.mjs:7704:15', wording='Error: EventChecker Failed: NTEvent serviceAndMethod:NodeIKernelMsgService/sendMsg ListenerName:NodeIKernelMsgListener/onMsgInfoListUpdate EventRet:\n{\n    "result": 120,\n    "errMsg": ""\n}\n\n    at file:///C:/Users/Administrator/Documents/LiteloaderQQNT/plugins/NapCat.Framework/napcat.mjs:7704:15', echo='4206')
01-04 18:01:05 [ERROR] zhenxun | CMD[被动查询微博热搜] [Target]([992333365:None]) 发送失败 || 错误 <class 'nonebot.adapters.onebot.v11.exception.ActionFailed'>: ActionFailed(status='failed', retcode=1200, data=None, message='Error: EventChecker Failed: NTEvent serviceAndMethod:NodeIKernelMsgService/sendMsg ListenerName:NodeIKernelMsgListener/onMsgInfoListUpdate EventRet:\n{\n    "result": 120,\n    "errMsg": ""\n}\n\n    at file:///C:/Users/Administrator/Documents/LiteloaderQQNT/plugins/NapCat.Framework/napcat.mjs:7704:15', wording='Error: EventChecker Failed: NTEvent serviceAndMethod:NodeIKernelMsgService/sendMsg ListenerName:NodeIKernelMsgListener/onMsgInfoListUpdate EventRet:\n{\n    "result": 120,\n    "errMsg": ""\n}\n\n    at file:///C:/Users/Administrator/Documents/LiteloaderQQNT/plugins/NapCat.Framework/napcat.mjs:7704:15', echo='4210')
01-04 23:59:01 [ERROR] zhenxun | CMD[被动早晚安] [Target]([992333365:None]) 发送失败 || 错误 <class 'nonebot.adapters.onebot.v11.exception.ActionFailed'>: ActionFailed(status='failed', retcode=1200, data=None, message='Error: EventChecker Failed: NTEvent serviceAndMethod:NodeIKernelMsgService/sendMsg ListenerName:NodeIKernelMsgListener/onMsgInfoListUpdate EventRet:\n{\n    "result": 120,\n    "errMsg": ""\n}\n\n    at file:///C:/Users/Administrator/Documents/LiteloaderQQNT/plugins/NapCat.Framework/napcat.mjs:7704:15', wording='Error: EventChecker Failed: NTEvent serviceAndMethod:NodeIKernelMsgService/sendMsg ListenerName:NodeIKernelMsgListener/onMsgInfoListUpdate EventRet:\n{\n    "result": 120,\n    "errMsg": ""\n}\n\n    at file:///C:/Users/Administrator/Documents/LiteloaderQQNT/plugins/NapCat.Framework/napcat.mjs:7704:15', echo='5020')
