09-18 23:18:44 [ERROR] uvicorn | Traceback (most recent call last):
  File "C:\Users\Administrator\AppData\Local\Programs\Python\Python310\lib\asyncio\runners.py", line 44, in run
    return loop.run_until_complete(main)
  File "C:\Users\Administrator\AppData\Local\Programs\Python\Python310\lib\asyncio\base_events.py", line 636, in run_until_complete
    self.run_forever()
  File "C:\Users\Administrator\AppData\Local\Programs\Python\Python310\lib\asyncio\windows_events.py", line 321, in run_forever
    super().run_forever()
  File "C:\Users\Administrator\AppData\Local\Programs\Python\Python310\lib\asyncio\base_events.py", line 603, in run_forever
    self._run_once()
  File "C:\Users\Administrator\AppData\Local\Programs\Python\Python310\lib\asyncio\base_events.py", line 1909, in _run_once
    handle._run()
  File "C:\Users\Administrator\AppData\Local\Programs\Python\Python310\lib\asyncio\events.py", line 80, in _run
    self._context.run(self._callback, *self._args)
  File "C:\Users\Administrator\AppData\Local\pypoetry\Cache\virtualenvs\zhenxun-bot-k9jvl_fX-py3.10\lib\site-packages\uvicorn\server.py", line 68, in serve
    with self.capture_signals():
  File "C:\Users\Administrator\AppData\Local\Programs\Python\Python310\lib\contextlib.py", line 142, in __exit__
    next(self.gen)
  File "C:\Users\Administrator\AppData\Local\pypoetry\Cache\virtualenvs\zhenxun-bot-k9jvl_fX-py3.10\lib\site-packages\uvicorn\server.py", line 328, in capture_signals
    signal.raise_signal(captured_signal)
KeyboardInterrupt

During handling of the above exception, another exception occurred:

Traceback (most recent call last):
  File "C:\Users\Administrator\AppData\Local\pypoetry\Cache\virtualenvs\zhenxun-bot-k9jvl_fX-py3.10\lib\site-packages\starlette\routing.py", line 700, in lifespan
    await receive()
  File "C:\Users\Administrator\AppData\Local\pypoetry\Cache\virtualenvs\zhenxun-bot-k9jvl_fX-py3.10\lib\site-packages\uvicorn\lifespan\on.py", line 137, in receive
    return await self.receive_queue.get()
  File "C:\Users\Administrator\AppData\Local\Programs\Python\Python310\lib\asyncio\queues.py", line 159, in get
    await getter
asyncio.exceptions.CancelledError

09-18 23:52:27 [ERROR] uvicorn | Traceback (most recent call last):
  File "C:\Users\Administrator\AppData\Local\Programs\Python\Python310\lib\asyncio\runners.py", line 44, in run
    return loop.run_until_complete(main)
  File "C:\Users\Administrator\AppData\Local\Programs\Python\Python310\lib\asyncio\base_events.py", line 636, in run_until_complete
    self.run_forever()
  File "C:\Users\Administrator\AppData\Local\Programs\Python\Python310\lib\asyncio\windows_events.py", line 321, in run_forever
    super().run_forever()
  File "C:\Users\Administrator\AppData\Local\Programs\Python\Python310\lib\asyncio\base_events.py", line 603, in run_forever
    self._run_once()
  File "C:\Users\Administrator\AppData\Local\Programs\Python\Python310\lib\asyncio\base_events.py", line 1909, in _run_once
    handle._run()
  File "C:\Users\Administrator\AppData\Local\Programs\Python\Python310\lib\asyncio\events.py", line 80, in _run
    self._context.run(self._callback, *self._args)
  File "C:\Users\Administrator\AppData\Local\pypoetry\Cache\virtualenvs\zhenxun-bot-k9jvl_fX-py3.10\lib\site-packages\uvicorn\server.py", line 68, in serve
    with self.capture_signals():
  File "C:\Users\Administrator\AppData\Local\Programs\Python\Python310\lib\contextlib.py", line 142, in __exit__
    next(self.gen)
  File "C:\Users\Administrator\AppData\Local\pypoetry\Cache\virtualenvs\zhenxun-bot-k9jvl_fX-py3.10\lib\site-packages\uvicorn\server.py", line 328, in capture_signals
    signal.raise_signal(captured_signal)
KeyboardInterrupt

During handling of the above exception, another exception occurred:

Traceback (most recent call last):
  File "C:\Users\Administrator\AppData\Local\pypoetry\Cache\virtualenvs\zhenxun-bot-k9jvl_fX-py3.10\lib\site-packages\starlette\routing.py", line 700, in lifespan
    await receive()
  File "C:\Users\Administrator\AppData\Local\pypoetry\Cache\virtualenvs\zhenxun-bot-k9jvl_fX-py3.10\lib\site-packages\uvicorn\lifespan\on.py", line 137, in receive
    return await self.receive_queue.get()
  File "C:\Users\Administrator\AppData\Local\Programs\Python\Python310\lib\asyncio\queues.py", line 159, in get
    await getter
asyncio.exceptions.CancelledError

