09-26 04:30:14 [ERROR] zhenxun | 更新色图 1.jpg 错误 <class 'FileExistsError'>: [WinError 183] 当文件已存在时，无法创建该文件。: 'resources\\temp\\1.jpg' -> 'resources\\image\\_setu\\1.jpg'
09-26 04:30:16 [ERROR] zhenxun | 更新色图 0.jpg 错误 <class 'FileExistsError'>: [WinError 183] 当文件已存在时，无法创建该文件。: 'resources\\temp\\0.jpg' -> 'resources\\image\\_setu\\0.jpg'
09-26 09:01:00 [ERROR] apscheduler | Job "_ (trigger: cron[hour='9', minute='1'], next run at: 2024-09-27 09:01:00 CST)" raised an exception
Traceback (most recent call last):

  File "C:\Program Files\zhenxun\zhenxun_bot-dev\bot.py", line 27, in <module>
    nonebot.run()
    │       └ <function run at 0x00000174828D5510>
    └ <module 'nonebot' from 'C:\\Users\\Administrator\\AppData\\Local\\pypoetry\\Cache\\virtualenvs\\zhenxun-bot-k9jvl_fX-py3.10\\...

  File "C:\Users\Administrator\AppData\Local\pypoetry\Cache\virtualenvs\zhenxun-bot-k9jvl_fX-py3.10\lib\site-packages\nonebot\__init__.py", line 335, in run
    get_driver().run(*args, **kwargs)
    │                 │       └ {}
    │                 └ ()
    └ <function get_driver at 0x00000174828D5360>

  File "C:\Users\Administrator\AppData\Local\pypoetry\Cache\virtualenvs\zhenxun-bot-k9jvl_fX-py3.10\lib\site-packages\nonebot\drivers\fastapi.py", line 186, in run
    uvicorn.run(
    │       └ <function run at 0x00000174830B2D40>
    └ <module 'uvicorn' from 'C:\\Users\\Administrator\\AppData\\Local\\pypoetry\\Cache\\virtualenvs\\zhenxun-bot-k9jvl_fX-py3.10\\...

  File "C:\Users\Administrator\AppData\Local\pypoetry\Cache\virtualenvs\zhenxun-bot-k9jvl_fX-py3.10\lib\site-packages\uvicorn\main.py", line 577, in run
    server.run()
    │      └ <function Server.run at 0x00000174830B2680>
    └ <uvicorn.server.Server object at 0x0000017492DA7C40>

  File "C:\Users\Administrator\AppData\Local\pypoetry\Cache\virtualenvs\zhenxun-bot-k9jvl_fX-py3.10\lib\site-packages\uvicorn\server.py", line 65, in run
    return asyncio.run(self.serve(sockets=sockets))
           │       │   │    │             └ None
           │       │   │    └ <function Server.serve at 0x00000174830B2710>
           │       │   └ <uvicorn.server.Server object at 0x0000017492DA7C40>
           │       └ <function run at 0x00000174805ECE50>
           └ <module 'asyncio' from 'C:\\Users\\Administrator\\AppData\\Local\\Programs\\Python\\Python310\\lib\\asyncio\\__init__.py'>

  File "C:\Users\Administrator\AppData\Local\Programs\Python\Python310\lib\asyncio\runners.py", line 44, in run
    return loop.run_until_complete(main)
           │    │                  └ <coroutine object Server.serve at 0x0000017493A07C30>
           │    └ <function BaseEventLoop.run_until_complete at 0x00000174806F0280>
           └ <ProactorEventLoop running=True closed=False debug=False>

  File "C:\Users\Administrator\AppData\Local\Programs\Python\Python310\lib\asyncio\base_events.py", line 636, in run_until_complete
    self.run_forever()
    │    └ <function ProactorEventLoop.run_forever at 0x000001748230D510>
    └ <ProactorEventLoop running=True closed=False debug=False>

  File "C:\Users\Administrator\AppData\Local\Programs\Python\Python310\lib\asyncio\windows_events.py", line 321, in run_forever
    super().run_forever()

  File "C:\Users\Administrator\AppData\Local\Programs\Python\Python310\lib\asyncio\base_events.py", line 603, in run_forever
    self._run_once()
    │    └ <function BaseEventLoop._run_once at 0x00000174806F1CF0>
    └ <ProactorEventLoop running=True closed=False debug=False>

  File "C:\Users\Administrator\AppData\Local\Programs\Python\Python310\lib\asyncio\base_events.py", line 1909, in _run_once
    handle._run()
    │      └ <function Handle._run at 0x00000174806A09D0>
    └ <Handle Task.task_wakeup(<Future finished result=None>)>

  File "C:\Users\Administrator\AppData\Local\Programs\Python\Python310\lib\asyncio\events.py", line 80, in _run
    self._context.run(self._callback, *self._args)
    │    │            │    │           │    └ <member '_args' of 'Handle' objects>
    │    │            │    │           └ <Handle Task.task_wakeup(<Future finished result=None>)>
    │    │            │    └ <member '_callback' of 'Handle' objects>
    │    │            └ <Handle Task.task_wakeup(<Future finished result=None>)>
    │    └ <member '_context' of 'Handle' objects>
    └ <Handle Task.task_wakeup(<Future finished result=None>)>

> File "C:\Users\Administrator\AppData\Local\pypoetry\Cache\virtualenvs\zhenxun-bot-k9jvl_fX-py3.10\lib\site-packages\apscheduler\executors\base_py3.py", line 30, in run_coroutine_job
    retval = await job.func(*job.args, **job.kwargs)
                   │   │     │   │       │   └ <member 'kwargs' of 'Job' objects>
                   │   │     │   │       └ <Job (id=053c5a15f5e1439ea5b54f8c24cc25cd name=_)>
                   │   │     │   └ <member 'args' of 'Job' objects>
                   │   │     └ <Job (id=053c5a15f5e1439ea5b54f8c24cc25cd name=_)>
                   │   └ <member 'func' of 'Job' objects>
                   └ <Job (id=053c5a15f5e1439ea5b54f8c24cc25cd name=_)>

  File "C:\Program Files\zhenxun\zhenxun_bot-dev\zhenxun\plugins\moyu.py", line 104, in _
    logger.info(f"发送摸鱼 {receipt}", arparma.header_result, session=session)
    │      └ <classmethod(<function logger.info at 0x00000174853637F0>)>
    └ <class 'zhenxun.services.log.logger'>

NameError: name 'arparma' is not defined
09-26 23:49:23 [ERROR] uvicorn | Traceback (most recent call last):
  File "C:\Users\Administrator\AppData\Local\Programs\Python\Python310\lib\asyncio\runners.py", line 44, in run
    return loop.run_until_complete(main)
  File "C:\Users\Administrator\AppData\Local\Programs\Python\Python310\lib\asyncio\base_events.py", line 636, in run_until_complete
    self.run_forever()
  File "C:\Users\Administrator\AppData\Local\Programs\Python\Python310\lib\asyncio\windows_events.py", line 321, in run_forever
    super().run_forever()
  File "C:\Users\Administrator\AppData\Local\Programs\Python\Python310\lib\asyncio\base_events.py", line 603, in run_forever
    self._run_once()
  File "C:\Users\Administrator\AppData\Local\Programs\Python\Python310\lib\asyncio\base_events.py", line 1909, in _run_once
    handle._run()
  File "C:\Users\Administrator\AppData\Local\Programs\Python\Python310\lib\asyncio\events.py", line 80, in _run
    self._context.run(self._callback, *self._args)
  File "C:\Users\Administrator\AppData\Local\pypoetry\Cache\virtualenvs\zhenxun-bot-k9jvl_fX-py3.10\lib\site-packages\uvicorn\server.py", line 68, in serve
    with self.capture_signals():
  File "C:\Users\Administrator\AppData\Local\Programs\Python\Python310\lib\contextlib.py", line 142, in __exit__
    next(self.gen)
  File "C:\Users\Administrator\AppData\Local\pypoetry\Cache\virtualenvs\zhenxun-bot-k9jvl_fX-py3.10\lib\site-packages\uvicorn\server.py", line 328, in capture_signals
    signal.raise_signal(captured_signal)
KeyboardInterrupt

During handling of the above exception, another exception occurred:

Traceback (most recent call last):
  File "C:\Users\Administrator\AppData\Local\pypoetry\Cache\virtualenvs\zhenxun-bot-k9jvl_fX-py3.10\lib\site-packages\nonebot\drivers\fastapi.py", line 155, in _lifespan_manager
    yield
  File "C:\Users\Administrator\AppData\Local\pypoetry\Cache\virtualenvs\zhenxun-bot-k9jvl_fX-py3.10\lib\site-packages\starlette\routing.py", line 700, in lifespan
    await receive()
  File "C:\Users\Administrator\AppData\Local\pypoetry\Cache\virtualenvs\zhenxun-bot-k9jvl_fX-py3.10\lib\site-packages\uvicorn\lifespan\on.py", line 137, in receive
    return await self.receive_queue.get()
  File "C:\Users\Administrator\AppData\Local\Programs\Python\Python310\lib\asyncio\queues.py", line 159, in get
    await getter
asyncio.exceptions.CancelledError

During handling of the above exception, another exception occurred:

Traceback (most recent call last):
  File "C:\Users\Administrator\AppData\Local\pypoetry\Cache\virtualenvs\zhenxun-bot-k9jvl_fX-py3.10\lib\site-packages\starlette\routing.py", line 693, in lifespan
    async with self.lifespan_context(app) as maybe_state:
  File "C:\Users\Administrator\AppData\Local\Programs\Python\Python310\lib\contextlib.py", line 217, in __aexit__
    await self.gen.athrow(typ, value, traceback)
  File "C:\Users\Administrator\AppData\Local\pypoetry\Cache\virtualenvs\zhenxun-bot-k9jvl_fX-py3.10\lib\site-packages\nonebot\drivers\fastapi.py", line 157, in _lifespan_manager
    await self._lifespan.shutdown()
  File "C:\Users\Administrator\AppData\Local\pypoetry\Cache\virtualenvs\zhenxun-bot-k9jvl_fX-py3.10\lib\site-packages\nonebot\internal\driver\_lifespan.py", line 49, in shutdown
    await self._run_lifespan_func(self._shutdown_funcs)
  File "C:\Users\Administrator\AppData\Local\pypoetry\Cache\virtualenvs\zhenxun-bot-k9jvl_fX-py3.10\lib\site-packages\nonebot\internal\driver\_lifespan.py", line 36, in _run_lifespan_func
    await cast(ASYNC_LIFESPAN_FUNC, func)()
  File "C:\Users\Administrator\AppData\Local\pypoetry\Cache\virtualenvs\zhenxun-bot-k9jvl_fX-py3.10\lib\site-packages\nonebot_plugin_htmlrender\__init__.py", line 45, in shutdown
    await shutdown_browser()
  File "C:\Users\Administrator\AppData\Local\pypoetry\Cache\virtualenvs\zhenxun-bot-k9jvl_fX-py3.10\lib\site-packages\nonebot_plugin_htmlrender\browser.py", line 79, in shutdown_browser
    await _browser.close()
  File "C:\Users\Administrator\AppData\Local\pypoetry\Cache\virtualenvs\zhenxun-bot-k9jvl_fX-py3.10\lib\site-packages\playwright\async_api\_generated.py", line 13895, in close
    return mapping.from_maybe_impl(await self._impl_obj.close(reason=reason))
  File "C:\Users\Administrator\AppData\Local\pypoetry\Cache\virtualenvs\zhenxun-bot-k9jvl_fX-py3.10\lib\site-packages\playwright\_impl\_browser.py", line 189, in close
    await self._channel.send("close", {"reason": reason})
  File "C:\Users\Administrator\AppData\Local\pypoetry\Cache\virtualenvs\zhenxun-bot-k9jvl_fX-py3.10\lib\site-packages\playwright\_impl\_connection.py", line 59, in send
    return await self._connection.wrap_api_call(
  File "C:\Users\Administrator\AppData\Local\pypoetry\Cache\virtualenvs\zhenxun-bot-k9jvl_fX-py3.10\lib\site-packages\playwright\_impl\_connection.py", line 508, in wrap_api_call
    st: List[inspect.FrameInfo] = getattr(task, "__pw_stack__", inspect.stack())
  File "C:\Users\Administrator\AppData\Local\Programs\Python\Python310\lib\inspect.py", line 1673, in stack
    return getouterframes(sys._getframe(1), context)
  File "C:\Users\Administrator\AppData\Local\Programs\Python\Python310\lib\inspect.py", line 1650, in getouterframes
    frameinfo = (frame,) + getframeinfo(frame, context)
  File "C:\Users\Administrator\AppData\Local\Programs\Python\Python310\lib\inspect.py", line 1620, in getframeinfo
    filename = getsourcefile(frame) or getfile(frame)
  File "C:\Users\Administrator\AppData\Local\Programs\Python\Python310\lib\inspect.py", line 817, in getsourcefile
    filename = getfile(object)
KeyboardInterrupt

