10-23 01:24:59 [ERROR] nonebot | Failed to import "pa"
Traceback (most recent call last):

  File "C:\Program Files\zhenxun\zhenxun_bot-dev\bot.py", line 24, in <module>
    nonebot.load_plugins("zhenxun/plugins")
    │       └ <function load_plugins at 0x0000023119B35900>
    └ <module 'nonebot' from 'C:\\Users\\Administrator\\AppData\\Local\\pypoetry\\Cache\\virtualenvs\\zhenxun-bot-k9jvl_fX-py3.10\\...

  File "C:\Users\Administrator\AppData\Local\pypoetry\Cache\virtualenvs\zhenxun-bot-k9jvl_fX-py3.10\lib\site-packages\nonebot\plugin\load.py", line 51, in load_plugins
    return manager.load_all_plugins()
           │       └ <function PluginManager.load_all_plugins at 0x0000023119B341F0>
           └ PluginManager(available_plugins={'ai': 'zhenxun.plugins.ai', 'bilibili_sub': 'zhenxun.plugins.bilibili_sub', 'black_word': 'z...

  File "C:\Users\Administrator\AppData\Local\pypoetry\Cache\virtualenvs\zhenxun-bot-k9jvl_fX-py3.10\lib\site-packages\nonebot\plugin\manager.py", line 203, in load_all_plugins
    return set(

  File "C:\Users\Administrator\AppData\Local\pypoetry\Cache\virtualenvs\zhenxun-bot-k9jvl_fX-py3.10\lib\site-packages\nonebot\plugin\manager.py", line 204, in <genexpr>
    filter(None, (self.load_plugin(name) for name in self.available_plugins))
                  │    │           │         │       │    └ <property object at 0x0000023119B2DD50>
                  │    │           │         │       └ PluginManager(available_plugins={'ai': 'zhenxun.plugins.ai', 'bilibili_sub': 'zhenxun.plugins.bilibili_sub', 'black_word': 'z...
                  │    │           │         └ 'pa'
                  │    │           └ 'pa'
                  │    └ <function PluginManager.load_plugin at 0x0000023119B34160>
                  └ PluginManager(available_plugins={'ai': 'zhenxun.plugins.ai', 'bilibili_sub': 'zhenxun.plugins.bilibili_sub', 'black_word': 'z...

> File "C:\Users\Administrator\AppData\Local\pypoetry\Cache\virtualenvs\zhenxun-bot-k9jvl_fX-py3.10\lib\site-packages\nonebot\plugin\manager.py", line 169, in load_plugin
    module = importlib.import_module(self._searched_plugin_ids[name])
             │         │             │    │                    └ 'pa'
             │         │             │    └ {'ai': 'zhenxun.plugins.ai', 'bilibili_sub': 'zhenxun.plugins.bilibili_sub', 'black_word': 'zhenxun.plugins.black_word', 'bt'...
             │         │             └ PluginManager(available_plugins={'ai': 'zhenxun.plugins.ai', 'bilibili_sub': 'zhenxun.plugins.bilibili_sub', 'black_word': 'z...
             │         └ <function import_module at 0x0000023116EE5090>
             └ <module 'importlib' from 'C:\\Users\\Administrator\\AppData\\Local\\Programs\\Python\\Python310\\lib\\importlib\\__init__.py'>

  File "C:\Users\Administrator\AppData\Local\Programs\Python\Python310\lib\importlib\__init__.py", line 126, in import_module
    return _bootstrap._gcd_import(name[level:], package, level)
           │          │           │    │        │        └ 0
           │          │           │    │        └ None
           │          │           │    └ 0
           │          │           └ 'zhenxun.plugins.pa'
           │          └ <function _gcd_import at 0x0000023116D93490>
           └ <module '_frozen_importlib' (frozen)>

  File "<frozen importlib._bootstrap>", line 1050, in _gcd_import
  File "<frozen importlib._bootstrap>", line 1027, in _find_and_load
  File "<frozen importlib._bootstrap>", line 1006, in _find_and_load_unlocked
  File "<frozen importlib._bootstrap>", line 688, in _load_unlocked

  File "C:\Users\Administrator\AppData\Local\pypoetry\Cache\virtualenvs\zhenxun-bot-k9jvl_fX-py3.10\lib\site-packages\nonebot\plugin\manager.py", line 255, in exec_module
    super().exec_module(module)
                        └ <module 'zhenxun.plugins.pa' from 'C:\\Program Files\\zhenxun\\zhenxun_bot-dev\\zhenxun\\plugins\\pa\\__init__.py'>

  File "<frozen importlib._bootstrap_external>", line 883, in exec_module
  File "<frozen importlib._bootstrap>", line 241, in _call_with_frames_removed

  File "C:\Program Files\zhenxun\zhenxun_bot-dev\zhenxun\plugins\pa\__init__.py", line 12, in <module>
    from zhenxun.services.plugin_init import PluginInit

ModuleNotFoundError: No module named 'zhenxun.services.plugin_init'
10-23 03:01:00 [ERROR] apscheduler | Job "_ (trigger: cron[hour='3', minute='1'], next run at: 2024-10-24 03:01:00 CST)" raised an exception
Traceback (most recent call last):

  File "C:\Program Files\zhenxun\zhenxun_bot-dev\zhenxun\plugins\nonebot_plugin_sparkapi\config.py", line 129, in _
    clear_sign_data_pic()
    └ <function clear_sign_data_pic at 0x00000231288BB520>

  File "C:\Program Files\zhenxun\zhenxun_bot-dev\zhenxun\plugins\nonebot_plugin_sparkapi\config.py", line 138, in clear_sign_data_pic
    Path(DATA_PATH).rmdir()
    │    └ WindowsPath('C:/Users/Administrator/AppData/Local/nonebot2/nonebot_plugin_sparkapi')
    └ <class 'pathlib.Path'>

  File "C:\Users\Administrator\AppData\Local\Programs\Python\Python310\lib\pathlib.py", line 1215, in rmdir
    self._accessor.rmdir(self)
    │    │         │     └ WindowsPath('C:/Users/Administrator/AppData/Local/nonebot2/nonebot_plugin_sparkapi')
    │    │         └ <built-in function rmdir>
    │    └ <pathlib._NormalAccessor object at 0x000002311718D750>
    └ WindowsPath('C:/Users/Administrator/AppData/Local/nonebot2/nonebot_plugin_sparkapi')

OSError: [WinError 145] 目录不是空的。: 'C:\\Users\\Administrator\\AppData\\Local\\nonebot2\\nonebot_plugin_sparkapi'


During handling of the above exception, another exception occurred:


Traceback (most recent call last):

  File "C:\Program Files\zhenxun\zhenxun_bot-dev\bot.py", line 27, in <module>
    nonebot.run()
    │       └ <function run at 0x0000023119A05510>
    └ <module 'nonebot' from 'C:\\Users\\Administrator\\AppData\\Local\\pypoetry\\Cache\\virtualenvs\\zhenxun-bot-k9jvl_fX-py3.10\\...

  File "C:\Users\Administrator\AppData\Local\pypoetry\Cache\virtualenvs\zhenxun-bot-k9jvl_fX-py3.10\lib\site-packages\nonebot\__init__.py", line 335, in run
    get_driver().run(*args, **kwargs)
    │                 │       └ {}
    │                 └ ()
    └ <function get_driver at 0x0000023119A05360>

  File "C:\Users\Administrator\AppData\Local\pypoetry\Cache\virtualenvs\zhenxun-bot-k9jvl_fX-py3.10\lib\site-packages\nonebot\drivers\fastapi.py", line 186, in run
    uvicorn.run(
    │       └ <function run at 0x000002311A1DED40>
    └ <module 'uvicorn' from 'C:\\Users\\Administrator\\AppData\\Local\\pypoetry\\Cache\\virtualenvs\\zhenxun-bot-k9jvl_fX-py3.10\\...

  File "C:\Users\Administrator\AppData\Local\pypoetry\Cache\virtualenvs\zhenxun-bot-k9jvl_fX-py3.10\lib\site-packages\uvicorn\main.py", line 577, in run
    server.run()
    │      └ <function Server.run at 0x000002311A1DE680>
    └ <uvicorn.server.Server object at 0x000002312A316560>

  File "C:\Users\Administrator\AppData\Local\pypoetry\Cache\virtualenvs\zhenxun-bot-k9jvl_fX-py3.10\lib\site-packages\uvicorn\server.py", line 65, in run
    return asyncio.run(self.serve(sockets=sockets))
           │       │   │    │             └ None
           │       │   │    └ <function Server.serve at 0x000002311A1DE710>
           │       │   └ <uvicorn.server.Server object at 0x000002312A316560>
           │       └ <function run at 0x00000231176FCE50>
           └ <module 'asyncio' from 'C:\\Users\\Administrator\\AppData\\Local\\Programs\\Python\\Python310\\lib\\asyncio\\__init__.py'>

  File "C:\Users\Administrator\AppData\Local\Programs\Python\Python310\lib\asyncio\runners.py", line 44, in run
    return loop.run_until_complete(main)
           │    │                  └ <coroutine object Server.serve at 0x000002311C500DD0>
           │    └ <function BaseEventLoop.run_until_complete at 0x0000023117800280>
           └ <ProactorEventLoop running=True closed=False debug=False>

  File "C:\Users\Administrator\AppData\Local\Programs\Python\Python310\lib\asyncio\base_events.py", line 636, in run_until_complete
    self.run_forever()
    │    └ <function ProactorEventLoop.run_forever at 0x0000023119441510>
    └ <ProactorEventLoop running=True closed=False debug=False>

  File "C:\Users\Administrator\AppData\Local\Programs\Python\Python310\lib\asyncio\windows_events.py", line 321, in run_forever
    super().run_forever()

  File "C:\Users\Administrator\AppData\Local\Programs\Python\Python310\lib\asyncio\base_events.py", line 603, in run_forever
    self._run_once()
    │    └ <function BaseEventLoop._run_once at 0x0000023117801CF0>
    └ <ProactorEventLoop running=True closed=False debug=False>

  File "C:\Users\Administrator\AppData\Local\Programs\Python\Python310\lib\asyncio\base_events.py", line 1909, in _run_once
    handle._run()
    │      └ <function Handle._run at 0x00000231177B09D0>
    └ <Handle <TaskStepMethWrapper object at 0x000002312AC11090>()>

  File "C:\Users\Administrator\AppData\Local\Programs\Python\Python310\lib\asyncio\events.py", line 80, in _run
    self._context.run(self._callback, *self._args)
    │    │            │    │           │    └ <member '_args' of 'Handle' objects>
    │    │            │    │           └ <Handle <TaskStepMethWrapper object at 0x000002312AC11090>()>
    │    │            │    └ <member '_callback' of 'Handle' objects>
    │    │            └ <Handle <TaskStepMethWrapper object at 0x000002312AC11090>()>
    │    └ <member '_context' of 'Handle' objects>
    └ <Handle <TaskStepMethWrapper object at 0x000002312AC11090>()>

> File "C:\Users\Administrator\AppData\Local\pypoetry\Cache\virtualenvs\zhenxun-bot-k9jvl_fX-py3.10\lib\site-packages\apscheduler\executors\base_py3.py", line 30, in run_coroutine_job
    retval = await job.func(*job.args, **job.kwargs)
                   │   │     │   │       │   └ <member 'kwargs' of 'Job' objects>
                   │   │     │   │       └ <Job (id=dae88d9b5af243ffa107df0c81600284 name=_)>
                   │   │     │   └ <member 'args' of 'Job' objects>
                   │   │     └ <Job (id=dae88d9b5af243ffa107df0c81600284 name=_)>
                   │   └ <member 'func' of 'Job' objects>
                   └ <Job (id=dae88d9b5af243ffa107df0c81600284 name=_)>

  File "C:\Program Files\zhenxun\zhenxun_bot-dev\zhenxun\plugins\nonebot_plugin_sparkapi\config.py", line 132, in _
    logger.error("清理AI日常聊天数据失败...", e=e)

NameError: name 'logger' is not defined
10-23 04:30:05 [ERROR] zhenxun | 更新色图 6.jpg 错误 <class 'FileExistsError'>: [WinError 183] 当文件已存在时，无法创建该文件。: 'resources\\temp\\6.jpg' -> 'resources\\image\\_setu\\6.jpg'
10-23 04:30:08 [ERROR] zhenxun | 更新色图 5.jpg 错误 <class 'FileExistsError'>: [WinError 183] 当文件已存在时，无法创建该文件。: 'resources\\temp\\5.jpg' -> 'resources\\image\\_setu\\5.jpg'
10-23 04:30:33 [ERROR] zhenxun | 更新色图 3.jpg 错误 <class 'FileExistsError'>: [WinError 183] 当文件已存在时，无法创建该文件。: 'resources\\temp\\3.jpg' -> 'resources\\image\\_setu\\3.jpg'
10-23 04:30:37 [ERROR] zhenxun | 更新色图 1.jpg 错误 <class 'FileExistsError'>: [WinError 183] 当文件已存在时，无法创建该文件。: 'resources\\temp\\1.jpg' -> 'resources\\image\\_setu\\1.jpg'
10-23 04:30:39 [ERROR] zhenxun | 更新色图 0.jpg 错误 <class 'FileExistsError'>: [WinError 183] 当文件已存在时，无法创建该文件。: 'resources\\temp\\0.jpg' -> 'resources\\image\\_setu\\0.jpg'
