02-17 03:01:00 [ERROR] zhenxun | 清理AI日常聊天数据失败... || 错误 <class 'FileNotFoundError'>: [WinError 3] 系统找不到指定的路径。: 'C:\\Users\\Administrator\\AppData\\Local\\nonebot2\\nonebot_plugin_sparkapi'
02-17 04:30:09 [ERROR] zhenxun | 更新色图 4.jpg 错误 <class 'FileExistsError'>: [WinError 183] 当文件已存在时，无法创建该文件。: 'resources\\temp\\4.jpg' -> 'resources\\image\\_setu\\4.jpg'
02-17 04:30:12 [ERROR] zhenxun | 更新色图 3.jpg 错误 <class 'FileExistsError'>: [WinError 183] 当文件已存在时，无法创建该文件。: 'resources\\temp\\3.jpg' -> 'resources\\image\\_setu\\3.jpg'
02-17 06:01:10 [ERROR] zhenxun | CMD[被动早晚安] [Target]([992333365:None]) 发送失败 || 错误 <class 'nonebot.adapters.onebot.v11.exception.ActionFailed'>: ActionFailed(status='failed', retcode=1200, data=None, message='Error: Timeout: NTEvent serviceAndMethod:NodeIKernelMsgService/sendMsg ListenerName:NodeIKernelMsgListener/onMsgInfoListUpdate EventRet:\n{}\n\n    at Timeout.sendDataCallback [as _onTimeout] (file:///C:/Users/Administrator/Documents/LiteloaderQQNT/plugins/NapCat.Framework/napcat.mjs:7666:15)\n    at listOnTimeout (node:internal/timers:573:17)\n    at process.processTimers (node:internal/timers:514:7)', wording='Error: Timeout: NTEvent serviceAndMethod:NodeIKernelMsgService/sendMsg ListenerName:NodeIKernelMsgListener/onMsgInfoListUpdate EventRet:\n{}\n\n    at Timeout.sendDataCallback [as _onTimeout] (file:///C:/Users/Administrator/Documents/LiteloaderQQNT/plugins/NapCat.Framework/napcat.mjs:7666:15)\n    at listOnTimeout (node:internal/timers:573:17)\n    at process.processTimers (node:internal/timers:514:7)', echo='5757')
02-17 09:01:10 [ERROR] zhenxun | CMD[被动每日新闻] [Target]([992333365:None]) 发送失败 || 错误 <class 'nonebot.adapters.onebot.v11.exception.ActionFailed'>: ActionFailed(status='failed', retcode=1200, data=None, message='Error: Timeout: NTEvent serviceAndMethod:NodeIKernelMsgService/sendMsg ListenerName:NodeIKernelMsgListener/onMsgInfoListUpdate EventRet:\n{}\n\n    at Timeout.sendDataCallback [as _onTimeout] (file:///C:/Users/Administrator/Documents/LiteloaderQQNT/plugins/NapCat.Framework/napcat.mjs:7666:15)\n    at listOnTimeout (node:internal/timers:573:17)\n    at process.processTimers (node:internal/timers:514:7)', wording='Error: Timeout: NTEvent serviceAndMethod:NodeIKernelMsgService/sendMsg ListenerName:NodeIKernelMsgListener/onMsgInfoListUpdate EventRet:\n{}\n\n    at Timeout.sendDataCallback [as _onTimeout] (file:///C:/Users/Administrator/Documents/LiteloaderQQNT/plugins/NapCat.Framework/napcat.mjs:7666:15)\n    at listOnTimeout (node:internal/timers:573:17)\n    at process.processTimers (node:internal/timers:514:7)', echo='6011')
02-17 09:01:20 [ERROR] zhenxun | CMD[被动每日新闻] [Target]([546881717:None]) 发送失败 || 错误 <class 'nonebot.adapters.onebot.v11.exception.ActionFailed'>: ActionFailed(status='failed', retcode=1200, data=None, message='Error: Timeout: NTEvent serviceAndMethod:NodeIKernelMsgService/sendMsg ListenerName:NodeIKernelMsgListener/onMsgInfoListUpdate EventRet:\n{}\n\n    at Timeout.sendDataCallback [as _onTimeout] (file:///C:/Users/Administrator/Documents/LiteloaderQQNT/plugins/NapCat.Framework/napcat.mjs:7666:15)\n    at listOnTimeout (node:internal/timers:573:17)\n    at process.processTimers (node:internal/timers:514:7)', wording='Error: Timeout: NTEvent serviceAndMethod:NodeIKernelMsgService/sendMsg ListenerName:NodeIKernelMsgListener/onMsgInfoListUpdate EventRet:\n{}\n\n    at Timeout.sendDataCallback [as _onTimeout] (file:///C:/Users/Administrator/Documents/LiteloaderQQNT/plugins/NapCat.Framework/napcat.mjs:7666:15)\n    at listOnTimeout (node:internal/timers:573:17)\n    at process.processTimers (node:internal/timers:514:7)', echo='6012')
02-17 09:01:45 [ERROR] zhenxun | CMD[被动每日新闻] [Target]([992333365:None]) 发送失败 || 错误 <class 'nonebot.adapters.onebot.v11.exception.ActionFailed'>: ActionFailed(status='failed', retcode=1200, data=None, message='Error: Timeout: NTEvent serviceAndMethod:NodeIKernelMsgService/sendMsg ListenerName:NodeIKernelMsgListener/onMsgInfoListUpdate EventRet:\n{}\n\n    at Timeout.sendDataCallback [as _onTimeout] (file:///C:/Users/Administrator/Documents/LiteloaderQQNT/plugins/NapCat.Framework/napcat.mjs:7666:15)\n    at listOnTimeout (node:internal/timers:573:17)\n    at process.processTimers (node:internal/timers:514:7)', wording='Error: Timeout: NTEvent serviceAndMethod:NodeIKernelMsgService/sendMsg ListenerName:NodeIKernelMsgListener/onMsgInfoListUpdate EventRet:\n{}\n\n    at Timeout.sendDataCallback [as _onTimeout] (file:///C:/Users/Administrator/Documents/LiteloaderQQNT/plugins/NapCat.Framework/napcat.mjs:7666:15)\n    at listOnTimeout (node:internal/timers:573:17)\n    at process.processTimers (node:internal/timers:514:7)', echo='6014')
02-17 09:02:08 [ERROR] zhenxun | CMD[被动每日新闻] [Target]([546881717:None]) 发送失败 || 错误 <class 'nonebot.adapters.onebot.v11.exception.ActionFailed'>: ActionFailed(status='failed', retcode=1200, data=None, message='Error: Timeout: NTEvent serviceAndMethod:NodeIKernelMsgService/sendMsg ListenerName:NodeIKernelMsgListener/onMsgInfoListUpdate EventRet:\n{}\n\n    at Timeout.sendDataCallback [as _onTimeout] (file:///C:/Users/Administrator/Documents/LiteloaderQQNT/plugins/NapCat.Framework/napcat.mjs:7666:15)\n    at listOnTimeout (node:internal/timers:573:17)\n    at process.processTimers (node:internal/timers:514:7)', wording='Error: Timeout: NTEvent serviceAndMethod:NodeIKernelMsgService/sendMsg ListenerName:NodeIKernelMsgListener/onMsgInfoListUpdate EventRet:\n{}\n\n    at Timeout.sendDataCallback [as _onTimeout] (file:///C:/Users/Administrator/Documents/LiteloaderQQNT/plugins/NapCat.Framework/napcat.mjs:7666:15)\n    at listOnTimeout (node:internal/timers:573:17)\n    at process.processTimers (node:internal/timers:514:7)', echo='6015')
02-17 11:12:40 [ERROR] nonebot | Error when running WebSocketConnection hook. Running cancelled!
Traceback (most recent call last):

  File "C:\Users\Administrator\AppData\Local\pypoetry\Cache\virtualenvs\zhenxun-bot-k9jvl_fX-py3.10\lib\site-packages\httpx\_transports\default.py", line 60, in map_httpcore_exceptions
    yield

  File "C:\Users\Administrator\AppData\Local\pypoetry\Cache\virtualenvs\zhenxun-bot-k9jvl_fX-py3.10\lib\site-packages\httpx\_transports\default.py", line 353, in handle_async_request
    resp = await self._pool.handle_async_request(req)
                 │    │     │                    └ <Request [b'POST']>
                 │    │     └ <function AsyncConnectionPool.handle_async_request at 0x000002161FCEEA70>
                 │    └ <httpcore.AsyncConnectionPool object at 0x0000021633C61540>
                 └ <httpx.AsyncHTTPTransport object at 0x0000021633C61E70>

  File "C:\Users\Administrator\AppData\Local\pypoetry\Cache\virtualenvs\zhenxun-bot-k9jvl_fX-py3.10\lib\site-packages\httpcore\_async\connection_pool.py", line 208, in handle_async_request
    raise UnsupportedProtocol(
          └ <class 'httpcore.UnsupportedProtocol'>

httpcore.UnsupportedProtocol: Request URL is missing an 'http://' or 'https://' protocol.


The above exception was the direct cause of the following exception:


Traceback (most recent call last):

  File "C:\Users\Administrator\AppData\Local\pypoetry\Cache\virtualenvs\zhenxun-bot-k9jvl_fX-py3.10\lib\site-packages\nonebot\adapters\onebot\v11\adapter.py", line 173, in _call_api
    response = await self.driver.request(request)
                     │    │      │       └ Request(method='POST', url='None/get_group_list')
                     │    │      └ <function Mixin.request at 0x000002162006DA20>
                     │    └ Driver(type='fastapi+httpx+websockets', adapters=3, bots=0)
                     └ Adapter(name='OneBot V11')

  File "C:\Users\Administrator\AppData\Local\pypoetry\Cache\virtualenvs\zhenxun-bot-k9jvl_fX-py3.10\lib\site-packages\nonebot\drivers\httpx.py", line 130, in request
    return await session.request(setup)
                 │       │       └ Request(method='POST', url='None/get_group_list')
                 │       └ <function Session.request at 0x000002162006D7E0>
                 └ <nonebot.drivers.httpx.Session object at 0x0000021633C63850>

  File "C:\Users\Administrator\AppData\Local\pypoetry\Cache\virtualenvs\zhenxun-bot-k9jvl_fX-py3.10\lib\site-packages\nonebot\drivers\httpx.py", line 76, in request
    response = await self.client.request(
                     │    └ <property object at 0x000002161FB7A660>
                     └ <nonebot.drivers.httpx.Session object at 0x0000021633C63850>

  File "C:\Users\Administrator\AppData\Local\pypoetry\Cache\virtualenvs\zhenxun-bot-k9jvl_fX-py3.10\lib\site-packages\httpx\_client.py", line 1533, in request
    return await self.send(request, auth=auth, follow_redirects=follow_redirects)
                 │    │    │             │                      └ <httpx._client.UseClientDefault object at 0x000002161FB818D0>
                 │    │    │             └ <httpx._client.UseClientDefault object at 0x000002161FB818D0>
                 │    │    └ <Request('POST', '/None/get_group_list')>
                 │    └ <function AsyncClient.send at 0x000002161FD1B130>
                 └ <httpx.AsyncClient object at 0x0000021633C615D0>

  File "C:\Users\Administrator\AppData\Local\pypoetry\Cache\virtualenvs\zhenxun-bot-k9jvl_fX-py3.10\lib\site-packages\httpx\_client.py", line 1620, in send
    response = await self._send_handling_auth(
                     │    └ <function AsyncClient._send_handling_auth at 0x000002161FD1B1C0>
                     └ <httpx.AsyncClient object at 0x0000021633C615D0>

  File "C:\Users\Administrator\AppData\Local\pypoetry\Cache\virtualenvs\zhenxun-bot-k9jvl_fX-py3.10\lib\site-packages\httpx\_client.py", line 1648, in _send_handling_auth
    response = await self._send_handling_redirects(
                     │    └ <function AsyncClient._send_handling_redirects at 0x000002161FD1B250>
                     └ <httpx.AsyncClient object at 0x0000021633C615D0>

  File "C:\Users\Administrator\AppData\Local\pypoetry\Cache\virtualenvs\zhenxun-bot-k9jvl_fX-py3.10\lib\site-packages\httpx\_client.py", line 1685, in _send_handling_redirects
    response = await self._send_single_request(request)
                     │    │                    └ <Request('POST', '/None/get_group_list')>
                     │    └ <function AsyncClient._send_single_request at 0x000002161FD1B2E0>
                     └ <httpx.AsyncClient object at 0x0000021633C615D0>

  File "C:\Users\Administrator\AppData\Local\pypoetry\Cache\virtualenvs\zhenxun-bot-k9jvl_fX-py3.10\lib\site-packages\httpx\_client.py", line 1722, in _send_single_request
    response = await transport.handle_async_request(request)
                     │         │                    └ <Request('POST', '/None/get_group_list')>
                     │         └ <function AsyncHTTPTransport.handle_async_request at 0x000002161FD188B0>
                     └ <httpx.AsyncHTTPTransport object at 0x0000021633C61E70>

  File "C:\Users\Administrator\AppData\Local\pypoetry\Cache\virtualenvs\zhenxun-bot-k9jvl_fX-py3.10\lib\site-packages\httpx\_transports\default.py", line 352, in handle_async_request
    with map_httpcore_exceptions():
         └ <function map_httpcore_exceptions at 0x000002161FC7C3A0>

  File "C:\Users\Administrator\AppData\Local\Programs\Python\Python310\lib\contextlib.py", line 153, in __exit__
    self.gen.throw(typ, value, traceback)
    │    │   │     │    │      └ <traceback object at 0x0000021634225800>
    │    │   │     │    └ UnsupportedProtocol("Request URL is missing an 'http://' or 'https://' protocol.")
    │    │   │     └ <class 'httpcore.UnsupportedProtocol'>
    │    │   └ <method 'throw' of 'generator' objects>
    │    └ <generator object map_httpcore_exceptions at 0x0000021634BFA570>
    └ <contextlib._GeneratorContextManager object at 0x0000021633C620E0>

  File "C:\Users\Administrator\AppData\Local\pypoetry\Cache\virtualenvs\zhenxun-bot-k9jvl_fX-py3.10\lib\site-packages\httpx\_transports\default.py", line 77, in map_httpcore_exceptions
    raise mapped_exc(message) from exc
          │          └ "Request URL is missing an 'http://' or 'https://' protocol."
          └ <class 'httpx.UnsupportedProtocol'>

httpx.UnsupportedProtocol: Request URL is missing an 'http://' or 'https://' protocol.


The above exception was the direct cause of the following exception:


Traceback (most recent call last):

  File "C:\Program Files\zhenxun\zhenxun_bot-dev\bot.py", line 27, in <module>
    nonebot.run()
    │       └ <function run at 0x000002161E6A6290>
    └ <module 'nonebot' from 'C:\\Users\\Administrator\\AppData\\Local\\pypoetry\\Cache\\virtualenvs\\zhenxun-bot-k9jvl_fX-py3.10\\...

  File "C:\Users\Administrator\AppData\Local\pypoetry\Cache\virtualenvs\zhenxun-bot-k9jvl_fX-py3.10\lib\site-packages\nonebot\__init__.py", line 335, in run
    get_driver().run(*args, **kwargs)
    │                 │       └ {}
    │                 └ ()
    └ <function get_driver at 0x000002161E6A60E0>

  File "C:\Users\Administrator\AppData\Local\pypoetry\Cache\virtualenvs\zhenxun-bot-k9jvl_fX-py3.10\lib\site-packages\nonebot\drivers\fastapi.py", line 186, in run
    uvicorn.run(
    │       └ <function run at 0x000002161EE7BD00>
    └ <module 'uvicorn' from 'C:\\Users\\Administrator\\AppData\\Local\\pypoetry\\Cache\\virtualenvs\\zhenxun-bot-k9jvl_fX-py3.10\\...

  File "C:\Users\Administrator\AppData\Local\pypoetry\Cache\virtualenvs\zhenxun-bot-k9jvl_fX-py3.10\lib\site-packages\uvicorn\main.py", line 579, in run
    server.run()
    │      └ <function Server.run at 0x000002161EE7B640>
    └ <uvicorn.server.Server object at 0x000002162EEC83A0>

  File "C:\Users\Administrator\AppData\Local\pypoetry\Cache\virtualenvs\zhenxun-bot-k9jvl_fX-py3.10\lib\site-packages\uvicorn\server.py", line 65, in run
    return asyncio.run(self.serve(sockets=sockets))
           │       │   │    │             └ None
           │       │   │    └ <function Server.serve at 0x000002161EE7B6D0>
           │       │   └ <uvicorn.server.Server object at 0x000002162EEC83A0>
           │       └ <function run at 0x000002161C390E50>
           └ <module 'asyncio' from 'C:\\Users\\Administrator\\AppData\\Local\\Programs\\Python\\Python310\\lib\\asyncio\\__init__.py'>

  File "C:\Users\Administrator\AppData\Local\Programs\Python\Python310\lib\asyncio\runners.py", line 44, in run
    return loop.run_until_complete(main)
           │    │                  └ <coroutine object Server.serve at 0x000002162ECE69D0>
           │    └ <function BaseEventLoop.run_until_complete at 0x000002161C490280>
           └ <ProactorEventLoop running=True closed=False debug=False>

  File "C:\Users\Administrator\AppData\Local\Programs\Python\Python310\lib\asyncio\base_events.py", line 636, in run_until_complete
    self.run_forever()
    │    └ <function ProactorEventLoop.run_forever at 0x000002161E0D1510>
    └ <ProactorEventLoop running=True closed=False debug=False>

  File "C:\Users\Administrator\AppData\Local\Programs\Python\Python310\lib\asyncio\windows_events.py", line 321, in run_forever
    super().run_forever()

  File "C:\Users\Administrator\AppData\Local\Programs\Python\Python310\lib\asyncio\base_events.py", line 603, in run_forever
    self._run_once()
    │    └ <function BaseEventLoop._run_once at 0x000002161C491CF0>
    └ <ProactorEventLoop running=True closed=False debug=False>

  File "C:\Users\Administrator\AppData\Local\Programs\Python\Python310\lib\asyncio\base_events.py", line 1909, in _run_once
    handle._run()
    │      └ <function Handle._run at 0x000002161C4409D0>
    └ <Handle Task.task_wakeup(<_GatheringFu...uest failed')>)>

  File "C:\Users\Administrator\AppData\Local\Programs\Python\Python310\lib\asyncio\events.py", line 80, in _run
    self._context.run(self._callback, *self._args)
    │    │            │    │           │    └ <member '_args' of 'Handle' objects>
    │    │            │    │           └ <Handle Task.task_wakeup(<_GatheringFu...uest failed')>)>
    │    │            │    └ <member '_callback' of 'Handle' objects>
    │    │            └ <Handle Task.task_wakeup(<_GatheringFu...uest failed')>)>
    │    └ <member '_context' of 'Handle' objects>
    └ <Handle Task.task_wakeup(<_GatheringFu...uest failed')>)>

> File "C:\Users\Administrator\AppData\Local\pypoetry\Cache\virtualenvs\zhenxun-bot-k9jvl_fX-py3.10\lib\site-packages\nonebot\internal\driver\abstract.py", line 168, in _run_hook
    await asyncio.gather(*coros)
          │       │       └ [<coroutine object run_coro_with_catch at 0x000002162F733B50>, <coroutine object run_coro_with_catch at 0x00000216341065E0>, ...
          │       └ <function gather at 0x000002161C46F520>
          └ <module 'asyncio' from 'C:\\Users\\Administrator\\AppData\\Local\\Programs\\Python\\Python310\\lib\\asyncio\\__init__.py'>

  File "C:\Users\Administrator\AppData\Local\pypoetry\Cache\virtualenvs\zhenxun-bot-k9jvl_fX-py3.10\lib\site-packages\nonebot\utils.py", line 236, in run_coro_with_catch
    return await coro
                 └ <coroutine object Dependent.__call__ at 0x000002162F732B20>

  File "C:\Users\Administrator\AppData\Local\pypoetry\Cache\virtualenvs\zhenxun-bot-k9jvl_fX-py3.10\lib\site-packages\nonebot\dependencies\__init__.py", line 94, in __call__
    return await cast(Callable[..., Awaitable[R]], self.call)(**values)
                 │    │             │         │    │    │       └ {'bot': Bot(type='OneBot V11', self_id='3973508735')}
                 │    │             │         │    │    └ <function _ at 0x0000021627D41BD0>
                 │    │             │         │    └ Dependent(call=_)
                 │    │             │         └ ~R
                 │    │             └ <class 'collections.abc.Awaitable'>
                 │    └ typing.Callable
                 └ <function cast at 0x000002161C2204C0>

  File "C:\Program Files\zhenxun\zhenxun_bot-dev\zhenxun\builtin_plugins\init\__init__.py", line 26, in _
    group_list, _ = await PlatformUtils.get_group_list(bot)
                          │             │              └ Bot(type='OneBot V11', self_id='3973508735')
                          │             └ <classmethod(<function PlatformUtils.get_group_list at 0x000002161FA3C940>)>
                          └ <class 'zhenxun.utils.platform.PlatformUtils'>

  File "C:\Program Files\zhenxun\zhenxun_bot-dev\zhenxun\utils\platform.py", line 424, in get_group_list
    group_list = await bot.get_group_list()
                       └ Bot(type='OneBot V11', self_id='3973508735')

  File "C:\Users\Administrator\AppData\Local\pypoetry\Cache\virtualenvs\zhenxun-bot-k9jvl_fX-py3.10\lib\site-packages\nonebot\internal\adapter\bot.py", line 122, in call_api
    raise exception
          └ NetWorkError(message='HTTP request failed')

  File "C:\Users\Administrator\AppData\Local\pypoetry\Cache\virtualenvs\zhenxun-bot-k9jvl_fX-py3.10\lib\site-packages\nonebot\internal\adapter\bot.py", line 97, in call_api
    result = await self.adapter._call_api(self, api, **data)
                   │    │       │         │     │      └ {}
                   │    │       │         │     └ 'get_group_list'
                   │    │       │         └ Bot(type='OneBot V11', self_id='3973508735')
                   │    │       └ <function Adapter._call_api at 0x000002161BF18820>
                   │    └ Adapter(name='OneBot V11')
                   └ Bot(type='OneBot V11', self_id='3973508735')

  File "C:\Users\Administrator\AppData\Local\pypoetry\Cache\virtualenvs\zhenxun-bot-k9jvl_fX-py3.10\lib\site-packages\nonebot\adapters\onebot\v11\adapter.py", line 187, in _call_api
    raise NetworkError("HTTP request failed") from e
          └ <class 'nonebot.adapters.onebot.v11.exception.NetworkError'>

nonebot.adapters.onebot.v11.exception.NetworkError: NetWorkError(message='HTTP request failed')
